Workbook

Sheet UG_NBT y2569-2571
A1: 0.95 | B1: 0.15 | F1: =G1*9650*12 -> 1.1128496e+08 | G1: =SUBTOTAL(9,G4:G201) -> 961.01 | L1: =SUBTOTAL(3,L4:L201) -> 172 | M1: =SUBTOTAL(3,M4:M201) -> 172 | N1: =SUBTOTAL(3,N4:N201) -> 172 | O1: =SUBTOTAL(9,O4:O201) -> 96426913 | P1: =SUBTOTAL(9,P4:P201) -> 50705470 | Q1: =SUBTOTAL(9,Q4:Q201) -> 0 | T1: =SUBTOTAL(3,T4:T201) -> 172 | U1: =SUBTOTAL(9,U4:U201) -> 633.9275 | V1: =SUBTOTAL(9,V4:V201) -> 182.9275 | W1: =SUBTOTAL(9,W4:W201) -> 814.355 | X1: =SUBTOTAL(3,X4:X201) -> 172 | Y1: =SUBTOTAL(3,Y4:Y201) -> 172
R2: Design | S2: Design | T2: Design | U2: Design | V2: Design | X2: Design | Y2: Design
A3: ลำดับ | B3: พื้นที่ | C3: จังหวัด | D3: หักเสา | E3: รหัสเส้นทาง | F3: เส้นทาง | G3: ระยะท่อ (กม.) | H3: UIH SC | I3: Year plan | J3: แผนท่อเสร็จ | K3: เริ่มตัด | L3: Status UIH | M3: Solution (plan) | N3: Fiber Sharing | O3: CAPEX (estimate) | P3: OPEX/year (estimate) | Q3: Budget of work | R3: พิกัดต้นทาง | S3: พิกัดปลายทาง | T3: OFC Type (A+B) | U3: (A)ระยะลงท่อ (km) | V3: (B) ระยะบนเสาไฟฟ้า (km) | W3: (A)+(B) ระยะรวม (km) | X3: ปีที่ใช้งบประมาณ | Y3: ไตรมาสที่ใช้งบประมาณ
A4: 1 | B4: กรุงเทพมหานครและปริมณฑล | C4: กรุงเทพมหานคร | D4: หักเสาไฟฟ้า | E4: UG66/MSN/0005 | F4: ถนนอังรีดูนังด์(พระรามที่ 1 -พระรามที่ 4) | G4: 3.6 | H4: BKK4 | I4: 2569 | J4: เสร็จแล้ว | K4: ตัดแล้ว | L4: Done | M4: ลงใต้ดิน | N4: yes | O4: 574206 | P4: 185280 | Q4: Approved | R4: 13.730941310301457, 100.53364854197581 | S4: 13.745285309076259, 100.53588236120147 | T4: 144C | U4: 3.42 | V4: 0.54 | W4: =U4+V4 -> 3.96 | X4: 2568 | Y4: Q3
A5: 2 | B5: กรุงเทพมหานครและปริมณฑล | C5: กรุงเทพมหานคร | D5: หักเสาไฟฟ้า | E5: UG66/MSN/0001 | F5: ถนนจรัญสนิทวงศ์ ช่วงที่ 2 (แยกบางพลัด - ถนนบรมราชชนนี) | G5: 3.7 | H5: BKK1 | I5: 2569 | J5: 45658 | K5: 46081 | L5: Done | M5: ลงใต้ดิน | N5: yes | O5: 920982.58 | P5: 495000 | Q5: Approved | R5: 13.784568460507492, 100.49439125627126 | S5: 13.773351404499168, 100.48190426894638 | T5: 144C | U5: 3.515 | V5: 0.555 | W5: =U5+V5 -> 4.07 | X5: 2568 | Y5: Q4
A6: 3 | B6: กรุงเทพมหานครและปริมณฑล | C6: กรุงเทพมหานคร | D6: ไม่หักเสาไฟฟ้า | E6: UG66/OTH/0018 | F6: ถนนเยาวราช โซนที่ 5 (2 ฝั่งถนน) (ถนนทรงสวัสดิ์ - ซุ้มประตูเฉลิมพระเกียรติ 6 รอบพระชนมพรรษา) | G6: 0.6 | H6: BKK4 | I6: 2569 | J6: 45716 | K6: 46064 | L6: Done | M6: ลงใต้ดิน | N6: yes | O6: 126596.98 | P6: 36775.272 | Q6: Approved | R6: 13.739407567111556, 100.51147056044779 | S6: 13.737353625608659, 100.51294350981958 | T6: 60C | U6: 0.57 | V6: 0.09 | W6: =U6+V6 -> 0.66 | X6: 2568 | Y6: Q4
A7: 4 | B7: กรุงเทพมหานครและปริมณฑล | C7: กรุงเทพมหานคร | D7: หักเสาไฟฟ้า | E7: UG68/MSN/0004 | F7: ถนนประชาราษฎร์ สาย 2 (2 ฝั่งถนน) (แยกบางโพ - แม่น้ำเจ้าพระยา) | G7: 0.5 | H7: BKK2 | I7: 2569 | J7: 45808 | K7: 46091 | L7: Done | M7: ลงใต้ดิน | N7: yes | O7: 28750 | P7: 14036.364 | Q7: Approved | R7: 13.80636889371856, 100.52158110006106 | S7: 13.806316740574633, 100.51924673175483 | T7: 60C | U7: 0.475 | V7: 0.075 | W7: =U7+V7 -> 0.55 | X7: 2569 | Y7: Q2
A8: 5 | B8: กรุงเทพมหานครและปริมณฑล | C8: กรุงเทพมหานคร | D8: หักเสาไฟฟ้า | E8: UG67/MSN/0001 | F8: ถนนประชาราษฎร์ สาย 2 (2 ฝั่งถนน) (แยกประชาชื่น - แยกบางโพ) | G8: 2.8 | H8: BKK2 | I8: 2569 | J8: 45808 | K8: 46077 | L8: Done | M8: ลงใต้ดิน | N8: yes | O8: 161000 | P8: 78603.636 | Q8: Approved | R8: 13.805650769000955, 100.5332038528518 | S8: 13.80636889371856, 100.52158110006106 | T8: 60C | U8: 2.66 | V8: 0.42 | W8: =U8+V8 -> 3.08 | X8: 2569 | Y8: Q2
A9: 6 | B9: กรุงเทพมหานครและปริมณฑล | C9: กรุงเทพมหานคร | D9: หักเสาไฟฟ้า | E9: UG66/MSN/0003 | F9: ถนนจรัญสนิทวงศ์ ช่วงที่ 2 (2 ฝั่งถนน) (ถนนบรมราชชนนี - ถนนสุทธาวาส) | G9: 3 | H9: BKK1 | I9: 2569 | J9: 45658 | K9: 46111 | L9: Done | M9: ลงใต้ดิน | N9: yes | O9: 637974.77 | P9: 313671.84 | Q9: Approved | R9: 13.773351404499168, 100.48190426894638 | S9: 13.762829108215561, 100.47280943699901 | T9: 60C | U9: 2.85 | V9: 0.45 | W9: =U9+V9 -> 3.3 | X9: 2568 | Y9: Q1
A10: 7 | B10: กรุงเทพมหานครและปริมณฑล | C10: กรุงเทพมหานคร | D10: ไม่หักเสาไฟฟ้า | E10: UG65/OTH/0001 | F10: ถนนมหาราช (2 ฝั่งถนน) (ถนนหน้าพระลาน - ถนนพระจันทร์) | G10: 1 | H10: BKK4 | I10: 2569 | J10: 45716 | K10: 46112 | L10: n/a | M10: ไม่มีโครงข่าย | N10: no | O10: 0 | P10: 0 | Q10: n/a | R10: 13.752349559081285, 100.48952032574502 | S10: 13.756307989636536, 100.48963246494628 | T10: n/a | U10: 0 | V10: 0 | W10: =U10+V10 -> 0 | X10: n/a | Y10: n/a
A11: 8 | B11: กรุงเทพมหานครและปริมณฑล | C11: กรุงเทพมหานคร | D11: ไม่หักเสาไฟฟ้า | E11: UG66/OTH/0013 | F11: ถนนดินสอ (2 ฝั่งถนน) (ถนนราชดำเนินกลาง - ถนนบำรุงเมือง) | G11: 1 | H11: BKK4 | I11: 2569 | J11: 45716 | K11: 46112 | L11: n/a | M11: ไม่มีโครงข่าย | N11: no | O11: 0 | P11: 0 | Q11: n/a | R11: 13.756336780416937, 100.50172473113246 | S11: 13.751996814090212, 100.50091911156224 | T11: n/a | U11: 0 | V11: 0 | W11: =U11+V11 -> 0 | X11: n/a | Y11: n/a
A12: 9 | B12: กรุงเทพมหานครและปริมณฑล | C12: กรุงเทพมหานคร | D12: ไม่หักเสาไฟฟ้า | E12: UG67/OTH/0007 | F12: ถนนพระจันทร์ (2 ฝั่งถนน) (ถนนมหาราช - ถนนหน้าพระธาตุ) | G12: 0.6 | H12: BKK4 | I12: 2569 | J12: 45716 | K12: 46112 | L12: n/a | M12: ไม่มีโครงข่าย | N12: no | O12: 0 | P12: 0 | Q12: n/a | R12: 13.756315478100502, 100.48962466125836 | S12: 13.755464330915798, 100.49212710949539 | T12: n/a | U12: 0 | V12: 0 | W12: =U12+V12 -> 0 | X12: n/a | Y12: n/a
A13: 10 | B13: กรุงเทพมหานครและปริมณฑล | C13: กรุงเทพมหานคร | D13: ไม่หักเสาไฟฟ้า | E13: UG67/OTH/0008 | F13: ถนนศิริพงษ์ (รอบศาลาว่าการ กทม.) (1 ฝั่งถนน) (ถนนดินสอ - ถนนบำรุงเมือง) | G13: 0.4 | H13: BKK4 | I13: 2569 | J13: 45716 | K13: 46112 | L13: Done | M13: Re-route | N13: no | O13: 32500 | P13: 11580 | Q13: Approved | R13: 13.754652717659106, 100.50137705611867 | S13: 13.751914974521213, 100.50199713785821 | T13: 12C | U13: 0.38 | V13: 0.06 | W13: =U13+V13 -> 0.44 | X13: 2568 | Y13: Q4
A14: 11 | B14: กรุงเทพมหานครและปริมณฑล | C14: กรุงเทพมหานคร | D14: ไม่หักเสาไฟฟ้า | E14: UG66/OTH/0017 | F14: ถนนเยาวราช โซนที่ 4 ฝั่งใต้ (1 ฝั่งถนน) (ถนนราชวงศ์ - ถนนทรงสวัสดิ์) | G14: 0.6 | H14: BKK4 | I14: 2569 | J14: 45716 | K14: 46064 | L14: Onprocess | M14: ลงใต้ดิน | N14: yes | O14: 126596.98 | P14: 36775.272 | Q14: Approved | R14: 13.742290754376612, 100.50694991095189 | S14: 13.739396707790819, 100.5113779307246 | T14: 60C | U14: 0.57 | V14: 0.09 | W14: =U14+V14 -> 0.66 | X14: 2568 | Y14: Q4
A15: 12 | B15: กรุงเทพมหานครและปริมณฑล | C15: กรุงเทพมหานคร | D15: หักเสาไฟฟ้า | E15: UG67/MSN/0005 | F15: ถนนลาดพร้าว ช่วงที่ 2 (2 ฝั่งถนน) (ถนนรัชดาภิเษก - ถนนประดิษฐมนูธรรม) | G15: 8.4 | H15: BKK2 | I15: 2569 | J15: 45961 | K15: 46142 | L15: Done | M15: ลงใต้ดิน | N15: yes | O15: 875435.26 | P15: 296626.15 | Q15: Approved | R15: 13.805411917542347, 100.57495144377492 | S15: 13.786437316477445, 100.60875437077863 | T15: 144C | U15: 7.98 | V15: 1.26 | W15: =U15+V15 -> 9.24 | X15: 2568 | Y15: Q4
A16: 13 | B16: กรุงเทพมหานครและปริมณฑล | C16: กรุงเทพมหานคร | D16: ไม่หักเสาไฟฟ้า | E16: UG66/OTH/0015 | F16: ถนนเยาวราช โซนที่ 2 ฝั่งเหนือ (1 ฝั่งถนน) (ถบนราชวงศ์ - ถนนทรงสวัสดิ์) | G16: 0.6 | H16: BKK4 | I16: 2569 | J16: 45716 | K16: 46064 | L16: Onprocess | M16: ลงใต้ดิน | N16: yes | O16: 126596.98 | P16: 36775.272 | Q16: Approved | R16: 13.742351981932222, 100.50699483795309 | S16: 13.739483313274192, 100.51143472095434 | T16: 60C | U16: 0.57 | V16: 0.09 | W16: =U16+V16 -> 0.66 | X16: 2568 | Y16: Q4
A17: 14 | B17: กรุงเทพมหานครและปริมณฑล | C17: กรุงเทพมหานคร | D17: หักเสาไฟฟ้า | E17: UG67/OTH/0003 | F17: ถนนวิทยุ ช่วงที่ 2 (2 ฝั่งถนน) (ถนนเพลินจิต - ถนนเพชรบุรี) | G17: 1.6 | H17: BKK4 | I17: 2569 | J17: 45838 | K17: 46173 | L17: Onprocess | M17: ลงใต้ดิน | N17: yes | O17: 166500 | P17: 86850 | Q17: Approved | R17: 13.743321627022501, 100.54756286403692 | S17: 13.749692752378785, 100.54859664430262 | T17: 144C | U17: 1.52 | V17: 0.24 | W17: =U17+V17 -> 1.76 | X17: 2569 | Y17: Q2
A18: 15 | B18: กรุงเทพมหานครและปริมณฑล | C18: กรุงเทพมหานคร | D18: หักเสาไฟฟ้า | E18: UG65/NTC/0010 | F18: ถนนพระราม 4 ช่วงที่ 2 (2 ฝั่งถนน) (สามย่านมิตรทาวน์ - แยกคลองเตย) | G18: 7.2 | H18: BKK4 | I18: 2569 | J18: 46081 | K18: 46181 | L18: Done | M18: ลงใต้ดิน | N18: no | O18: 5051985.3 | P18: 2417417.1 | Q18: Approved | R18: 13.733353800169416, 100.52750043205424 | S18: 13.720229321195605, 100.55906312982408 | T18: 144C | U18: 6.84 | V18: 1.08 | W18: =U18+V18 -> 7.92 | X18: 2567 | Y18: Q2
A19: 16 | B19: กรุงเทพมหานครและปริมณฑล | C19: กรุงเทพมหานคร | D19: หักเสาไฟฟ้า | E19: UG66/MSN/0002 | F19: ถนนจรัญสนิทวงศ์ ช่วงที่ 2 (2 ฝั่งอนน) (ถนนสุทธาวาส - ถนนพรานนก) | G19: 2 | H19: BKK1 | I19: 2569 | J19: 45658 | K19: 46203 | L19: Onprocess | M19: ลงใต้ดิน | N19: yes | O19: 425316.52 | P19: 209114.56 | Q19: Approved | R19: 13.762829108215561, 100.47280943699901 | S19: 13.754866084753044, 100.46941322132035 | T19: 60C | U19: 1.9 | V19: 0.3 | W19: =U19+V19 -> 2.2 | X19: 2568 | Y19: Q1
A20: 17 | B20: กรุงเทพมหานครและปริมณฑล | C20: กรุงเทพมหานคร | D20: ไม่หักเสาไฟฟ้า | E20: UG66/OTH/0016 | F20: ถนนเยาวราช โซนที่ 3 ฝั่งใต้ (1 ฝั่งถนน) (ถนนราชวงศ์ - ถนนจักรวรรดิ) | G20: 0.3 | H20: BKK4 | I20: 2569 | J20: 45716 | K20: 46064 | L20: Done | M20: ลงใต้ดิน | N20: yes | O20: 63298.49 | P20: 18387.636 | Q20: Approved | R20: 13.74235530894268, 100.5069216699699 | S20: 13.744095165929302, 100.50446746701284 | T20: 60C | U20: 0.285 | V20: 0.045 | W20: =U20+V20 -> 0.33 | X20: 2568 | Y20: Q4
A21: 18 | B21: กรุงเทพมหานครและปริมณฑล | C21: กรุงเทพมหานคร | D21: หักเสาไฟฟ้า | E21: UG68/OTH/0007 | F21: ถนนพระราม 9 ช่วงที่ 1 (2 ฝั่งถนน) (แยกถนนรัชดาภิเษก - คลองชวดใหญ่) | G21: 3.6 | H21: BKK3 | I21: 2569 | J21: 46081 | K21: 46229 | L21: Onprocess | M21: ลงใต้ดิน | N21: yes (Jastel) | O21: 822500 | P21: 405300 | Q21: Approved | R21: 13.75605722785821, 100.5649928410609 | S21: 13.754864464443239, 100.58105671390848 | T21: 144C | U21: 3.42 | V21: 0.54 | W21: =U21+V21 -> 3.96 | X21: 2569 | Y21: Q3
A22: 19 | B22: กรุงเทพมหานครและปริมณฑล | C22: นนทบุรี | D22: ไม่หักเสาไฟฟ้า | E22: UG65/OTH/0013 | F22: ถนนศรีสมาน (2 ฝั่งถนน) (แยกสวนสมเด็จพระศรีนครินทร์ - ถนนเลียบคลองประปา) | G22: 5.2 | H22: BKK2 | I22: 2569 | J22: 46173 | K22: 46234 | L22: Done | M22: ลงใต้ดิน | N22: yes | O22: 609637.44 | P22: 299150 | Q22: Approved | R22: 13.940560347819595, 100.54209283026739 | S22: 13.934430157181419, 100.56354359702038 | T22: 144C | U22: 4.94 | V22: 0.78 | W22: =U22+V22 -> 5.72 | X22: 2568 | Y22: Q4
A23: 20 | B23: กรุงเทพมหานครและปริมณฑล | C23: กรุงเทพมหานคร | D23: ไม่หักเสาไฟฟ้า | E23: UG66/OTH/0014 | F23: ถนนเยาวราช โซนที่ 1 ฝั่งเหนือ (1 ฝั่งถนน) (ถนนราชวงศ์ - ถนนจักรวรรดิ) | G23: 0.35 | H23: BKK4 | I23: 2569 | J23: 45716 | K23: 46064 | L23: Done | M23: ลงใต้ดิน | N23: yes | O23: 73848.239 | P23: 21452.242 | Q23: Approved | R23: 13.742402566193277, 100.50696074758135 | S23: 13.744195474119442, 100.50455061549454 | T23: 60C | U23: 0.3325 | V23: 0.0525 | W23: =U23+V23 -> 0.385 | X23: 2568 | Y23: Q4
A24: 21 | B24: กรุงเทพมหานครและปริมณฑล | C24: กรุงเทพมหานคร | D24: หักเสาไฟฟ้า | E24: UG65/OTH/0002 | F24: ถนนลูกหลวง (1 ฝั่งถนน) (ซอยลูกหลวง 1 - ถนนสามเสน) | G24: 2.3 | H24: BKK4 | I24: 2569 | J24: 45961 | K24: 46235 | L24: Wait Duct (NT) | M24: ลงใต้ดิน+Re-route | N24: yes | O24: 116400 | P24: 57900 | Q24: Request | R24: 13.754718045186001, 100.51747023999916 | S24: 13.769942382856494, 100.50399285429273 | T24: 60C | U24: 2.185 | V24: 0.345 | W24: =U24+V24 -> 2.53 | X24: 2570 | Y24: Q1
... A29: 26 | B29: กรุงเทพมหานครและปริมณฑล | C29: กรุงเทพมหานคร | D29: ไม่หักเสาไฟฟ้า | E29: UG65/OTH/0018 | F29: ถนนวิภาวดีรังสิต ช่วงที่ 4 (2 ฝั่งถนน) (แยกเกษตร - หลักสี่) | G29: 9.4 | H29: BKK2 | I29: 2569 | J29: 46234 | K29: 46305 | L29: Wait Duct (NT) | M29: ลงใต้ดิน | N29: yes | O29: 1212600 | P29: 653112 | Q29: Request | R29: 13.847561540502536, 100.56149019379637 | S29: 13.884322387369098, 100.58169030148558 | T29: 144C | U29: 8.93 | V29: 1.41 | W29: =U29+V29 -> 10.34 | X29: 2570 | Y29: Q2
A30: 27 | B30: กรุงเทพมหานครและปริมณฑล | C30: กรุงเทพมหานคร | D30: หักเสาไฟฟ้า | E30: UG69/MSN/0001 | F30: ถนนตก (2 ฝั่งถนน) (ถนนพระราม 3 - กฟน.ยานนาวา) | G30: 1.1 | H30: BKK4 | I30: 2569 | J30: 46568 | L30: Wait Duct (NT) | M30: Re-route | N30: no | O30: 33600 | P30: 23160 | Q30: Request | R30: 13.697176484650662, 100.49704267467271 | S30: 13.69308524940448, 100.4924692323161 | T30: 12C | U30: 1.045 | V30: 0.165 | W30: =U30+V30 -> 1.21 | X30: 2571 | Y30: Q1
A31: 28 | B31: กรุงเทพมหานครและปริมณฑล | C31: กรุงเทพมหานคร | D31: หักเสาไฟฟ้า | E31: UG68/MSN/0021 | F31: เทียมร่วมมิตร (2 ฝั่งถนน) (แยกศูนย์วัฒนธรรม - ประชาอุทิศ) | G31: 5 | H31: BKK2 | I31: 2569 | J31: 46660 | L31: Wait Duct (NT) | M31: ลงใต้ดิน | N31: yes | O31: 348300 | P31: 187596 | Q31: Request | R31: 13.762591425569118, 100.57265766550815 | S31: 13.769063091571814, 100.59284282032604 | T31: 60C | U31: 4.75 | V31: 0.75 | W31: =U31+V31 -> 5.5 | X31: 2571 | Y31: Q2
A32: 29 | B32: กรุงเทพมหานครและปริมณฑล | C32: กรุงเทพมหานคร | D32: หักเสาไฟฟ้า | E32: UG68/MSN/0020 | F32: ถนนรามคำแหง 1 (2 ฝั่งถนน) (แยกคลองตัน - ทางรถไฟ) | G32: 0.4 | H32: BKK3 | I32: 2569 | J32: 46234 | K32: 46325 | L32: Wait Duct (NT) | M32: ลงใต้ดิน | N32: yes | O32: 77400 | P32: 27792 | Q32: Request | R32: 13.740986406319568, 100.60075742356503 | S32: 13.742830113711666, 100.60144260439787 | T32: 144C | U32: 0.38 | V32: 0.06 | W32: =U32+V32 -> 0.44 | X32: 2570 | Y32: Q2
A33: 30 | B33: กรุงเทพมหานครและปริมณฑล | C33: กรุงเทพมหานคร | D33: หักเสาไฟฟ้า | E33: UG68/MSN/0025 | F33: ถนนรามคำแหง 1 (2 ฝั่งถนน) (ทางรถไฟ - แยกลำสาสี) | G33: 11.2 | H33: BKK3 | I33: 2569 | J33: 46142 | K33: 46325 | L33: Onprocess | M33: ลงใต้ดิน | N33: yes | O33: 1516443.6 | P33: 507342.56 | Q33: Approved | R33: 13.742830113711666, 100.60144260439787 | S33: 13.762676916859343, 100.64562951492596 | T33: 144C | U33: 10.64 | V33: 1.68 | W33: =U33+V33 -> 12.32 | X33: 2569 | Y33: Q1
A34: 31 | B34: กรุงเทพมหานครและปริมณฑล | C34: นนทบุรี | D34: หักเสาไฟฟ้า | E34: UG68/MSN/0009 | F34: ถนนแจ้งวัฒนะ ช่วงที่ 2 (2 ฝั่งถนน) (ห้าแยกปากเกร็ด - ทางพิเศษศรีรัช) | G34: 8.4 | H34: BKK2 | I34: 2569 | J34: 46203 | K34: 46327 | L34: Wait Duct (NT) | M34: ลงใต้ดิน | N34: no | O34: 1974000 | P34: 972720 | Q34: Request | R34: 13.907518910842692, 100.50426855225544 | S34: 13.899426717362157, 100.54274973571448 | T34: 144C | U34: 7.98 | V34: 1.26 | W34: =U34+V34 -> 9.24 | X34: 2570 | Y34: Q2
A35: 32 | B35: กรุงเทพมหานครและปริมณฑล | C35: กรุงเทพมหานคร | D35: หักเสาไฟฟ้า | E35: UG68/MSN/0022 | F35: ถนนบรมราชชนนี (2 ฝั่งถนน) (แยกอรุณ - สมเด็จพระปิ่นเกล้า-สายใต้เก่า) | G35: 5.6 | H35: BKK1 | I35: 2569 | J35: 46234 | K35: 46342 | L35: Wait Duct (NT) | M35: ลงใต้ดิน | N35: yes | O35: 538200 | P35: 319608 | Q35: Request | R35: 13.768484342823152, 100.48575350796152 | S35: 13.78747686967618, 100.46862468398734 | T35: 144C | U35: 5.32 | V35: 0.84 | W35: =U35+V35 -> 6.16 | X35: 2570 | Y35: Q3
A36: 33 | B36: กรุงเทพมหานครและปริมณฑล | C36: กรุงเทพมหานคร | D36: หักเสาไฟฟ้า | E36: UG68/MSN/0006 | F36: ถนนสาทร (2 ฝั่งถนน) (แยกถนนพระรามที่ 4 - ถนนเจริญกรุง) | G36: 6.6 | H36: BKK4 | I36: 2569 | J36: 46326 | K36: 46446 | L36: Wait Duct (NT) | M36: ลงใต้ดิน | N36: no | O36: 2437500 | P36: 868500 | Q36: Approved | R36: 13.72630499219555, 100.54443991593318 | S36: 13.71861788590893, 100.51513825939988 | T36: 216C | U36: 6.27 | V36: 0.99 | W36: =U36+V36 -> 7.26 | X36: 2569 | Y36: Q3
A37: 34 | B37: กรุงเทพมหานครและปริมณฑล | C37: กรุงเทพมหานคร | D37: ไม่หักเสาไฟฟ้า | E37: UG68/OTH/0001 | F37: ถนนทรงวาด (2 ฝั่งถนน) (ถนนราชวงศ์ - ถนนเจริญกรุง) | G37: 2.2 | H37: BKK4 | I37: 2569 | J37: 46203 | K37: 46345 | L37: Wait Duct (NT) | M37: ลงใต้ดิน | N37: yes | O37: 28800 | P37: 11580 | Q37: Request | R37: 13.739560982438089, 100.50483215284562 | S37: 13.736179726306444, 100.51354391848832 | T37: 60C | U37: 2.09 | V37: 0.33 | W37: =U37+V37 -> 2.42 | X37: 2570 | Y37: Q3
A38: 35 | B38: กรุงเทพมหานครและปริมณฑล | C38: กรุงเทพมหานคร | D38: ไม่หักเสาไฟฟ้า | E38: UG65/OTH/0007 | F38: ถนนวิภาวดีรังสิต (2 ฝั่งถนน) (ห้าแยกลาดพร้าว - แยกรัชวิภา) | G38: 3.8 | H38: BKK2 | I38: 2569 | J38: 46234 | K38: 46349 | L38: Wait Duct (NT) | M38: ลงใต้ดิน | N38: yes | O38: 490200 | P38: 264024 | Q38: Request | R38: 13.813637399905678, 100.5601922880701 | S38: 13.83061678294147, 100.55769289913887 | T38: 144C | U38: 3.61 | V38: 0.57 | W38: =U38+V38 -> 4.18 | X38: 2570 | Y38: Q3
A39: 36 | B39: กรุงเทพมหานครและปริมณฑล | C39: กรุงเทพมหานคร | D39: ไม่หักเสาไฟฟ้า | E39: UG65/OTH/0016 | F39: ถนนวิภาวดีรังสิต (2 ฝั่งถนน) (แยกรัชวิภา - ถนนงามวงศ์วาน) | G39: 4 | H39: BKK2 | I39: 2569 | J39: 46234 | K39: 46350 | L39: Wait Duct (NT) | M39: ลงใต้ดิน | N39: yes | O39: 516000 | P39: 277920 | Q39: Request | R39: 13.83061678294147, 100.55769289913887 | S39: 13.847539117538599, 100.56154407157679 | T39: 144C | U39: 3.8 | V39: 0.6 | W39: =U39+V39 -> 4.4 | X39: 2570 | Y39: Q3
A40: 37 | B40: กรุงเทพมหานครและปริมณฑล | C40: นนทบุรี | D40: หักเสาไฟฟ้า | E40: UG68/MSN/0003 | F40: ถนนติวานนท์ (2 ฝั่งถนน) (แยกกรุงเทพนนท์ - แยกแคราย) | G40: 7.6 | H40: BKK2 | I40: 2569 | J40: 46234 | K40: 46326 | L40: Wait Duct (NT) | M40: ลงใต้ดิน | N40: yes | O40: 774000 | P40: 416880 | Q40: Request | R40: 13.84298287114514, 100.51090893807161 | S40: 13.85902955876802, 100.52166995473303 | T40: 144C | U40: 7.22 | V40: 1.14 | W40: =U40+V40 -> 8.36 | X40: 2570 | Y40: Q2
A41: 38 | B41: กรุงเทพมหานครและปริมณฑล | C41: กรุงเทพมหานคร | D41: หักเสาไฟฟ้า | E41: UG68/MSN/0026 | F41: ถนนนครอินทร์ (2 ฝั่งถนน) (นครอินทร์ - กรุงเทพนนท์) | G41: 7.6 | H41: BKK2 | I41: 2569 | J41: 46387 | K41: 46350 | L41: Wait Duct (NT) | M41: ลงใต้ดิน+Re-route | N41: yes | O41: 516000 | P41: 277920 | Q41: Request | R41: 13.833026077932532, 100.49630051361952 | S41: 13.843006092864622, 100.51086234465382 | T41: 60C | U41: 7.22 | V41: 1.14 | W41: =U41+V41 -> 8.36 | X41: 2570 | Y41: Q2
A42: 39 | B42: กรุงเทพมหานครและปริมณฑล | C42: กรุงเทพมหานคร | D42: หักเสาไฟฟ้า | E42: UG65/NTC/0008 | F42: ถนนรัชดาภิเษก 2 (2 ฝั่งถนน) (ถนนเพชรบุรี - แยกสุทธิสาร) | G42: 9.6 | H42: BKK2 | I42: 2569 | J42: 46234 | K42: 46356 | L42: Wait Duct (NT) | M42: ลงใต้ดิน | N42: yes | O42: 1749000 | P42: 736488 | Q42: Request | R42: 13.748956008689177, 100.56338852059962 | S42: 13.789756397039273, 100.57417618016926 | T42: 144C | U42: 9.12 | V42: 1.44 | W42: =U42+V42 -> 10.56 | X42: 2570 | Y42: Q3
A43: 40 | B43: กรุงเทพมหานครและปริมณฑล | C43: กรุงเทพมหานคร | D43: หักเสาไฟฟ้า | E43: UG68/NTC/0013 | F43: ถนนเพชรบุรี ช่วงที่ 1 (2 ฝั่งถนน) (แยกคลองตัน - ทางรถไฟ) | G43: 11.2 | H43: BKK4 | I43: 2569 | J43: 46234 | K43: 46356 | L43: Wait Duct (NT) | M43: ลงใต้ดิน | N43: yes | O43: 1912500 | P43: 868500 | Q43: Request | R43: 13.740981230694201, 100.60078273605333 | S43: 13.749005091156855, 100.5634206550746 | T43: 144C | U43: 10.64 | V43: 1.68 | W43: =U43+V43 -> 12.32 | X43: 2570 | Y43: Q1
... A96: 93 | B96: กรุงเทพมหานครและปริมณฑล | C96: กรุงเทพมหานคร | D96: หักเสาไฟฟ้า | E96: UG70/MSN/0006 | F96: ถนนรามคำแหง 3 (ถนนร่มเกล้า - ถนนสุวินทวงศ์) | G96: 2 | H96: BKK3 | I96: 2571 | J96: 46752 | K96: 46965 | L96: Wait Duct (NT) | M96: ลงใต้ดิน | N96: yes | O96: 171000 | P96: 110010 | Q96: Request | R96: 13.81235267518258, 100.73685634680294 | S96: 13.816630274507467, 100.74463060181766 | T96: 60C | U96: 1.9 | V96: 0.3 | W96: =U96+V96 -> 2.2 | X96: 2571 | Y96: Q2
...

Sheet UG_NBT y2569-2571 (mat)
A1: 0.95 | B1: 0.15 | G1: =SUBTOTAL(9,G4:G201) -> 961.01 | L1: =SUBTOTAL(3,L4:L201) -> 172 | M1: =SUBTOTAL(3,M4:M201) -> 172 | N1: =SUBTOTAL(3,N4:N201) -> 172 | O1: =SUBTOTAL(9,O4:O201) -> 96426913 | P1: =SUBTOTAL(9,P4:P201) -> 50705470 | Q1: =SUBTOTAL(9,Q4:Q201) -> 0 | T1: =SUBTOTAL(3,T4:T201) -> 172 | U1: =SUBTOTAL(3,U4:U201) -> 7 | V1: =SUBTOTAL(3,V4:V201) -> 20 | W1: =SUBTOTAL(3,W4:W201) -> 61 | X1: =SUBTOTAL(3,X4:X201) -> 64 | Y1: =SUBTOTAL(3,Y4:Y201) -> 6 | AD1: =SUBTOTAL(9,AD4:AD201) -> 633.9275 | AE1: =SUBTOTAL(9,AE4:AE201) -> 182.9275 | AF1: =SUBTOTAL(9,AF4:AF201) -> 814.355 | AG1: =SUBTOTAL(3,AG4:AG201) -> 172 | AH1: =SUBTOTAL(3,AH4:AH201) -> 172
R2: Design | S2: Design | T2: Design | AD2: Design | AE2: Design | AG2: Design | AH2: Design
A3: ลำดับ | B3: พื้นที่ | C3: จังหวัด | D3: หักเสา | E3: รหัสเส้นทาง | F3: เส้นทาง | G3: ระยะท่อ (กม.) | H3: UIH SC | I3: Year plan | J3: แผนท่อเสร็จ | K3: เริ่มตัด | L3: Status UIH | M3: Solution (plan) | N3: Fiber Sharing | O3: CAPEX (estimate) | P3: OPEX/year (estimate) | Q3: Budget of work | R3: พิกัดต้นทาง | S3: พิกัดปลายทาง | T3: OFC Type (A+B) | U3: 12C | V3: 24C | W3: 60C | X3: 144C | Y3: 216C | Z3: Enclosure 12C/24C | AA3: Enclosure 60C | AB3: Enclosure 144C | AC3: Enclosure 312C | AD3: (A)ระยะลงท่อ (km) | AE3: (B) ระยะบนเสาไฟฟ้า (km) | AF3: (A)+(B) ระยะรวม (km) | AG3: ปีที่ใช้งบประมาณ | AH3: ไตรมาสที่ใช้งบประมาณ
A4: 1 | B4: กรุงเทพมหานครและปริมณฑล | C4: กรุงเทพมหานคร | D4: หักเสาไฟฟ้า | E4: UG66/MSN/0005 | F4: ถนนอังรีดูนังด์(พระรามที่ 1 -พระรามที่ 4) | G4: 3.6 | H4: BKK4 | I4: 2569 | J4: เสร็จแล้ว | K4: ตัดแล้ว | L4: Done | M4: ลงใต้ดิน | N4: yes | O4: 574206 | P4: 185280 | Q4: Approved | R4: 13.730941310301457, 100.53364854197581 | S4: 13.745285309076259, 100.53588236120147 | T4: 144C | X4: =AF4 -> 3.96 | Z4: {=_xlfn.LET( _xlpm.a,IF(ISNUMBER($U4),$U4,IFERROR(_xlfn.NUMBERVALUE(TRIM($U4)),0)), _xlpm.b,IF(ISNUMBER($V4),$V4,IFERROR(_xlfn.NUMBERVALUE(TRIM($V4)),0)), _xlpm.score,_xlfn.LAMBDA(_xlpm.x,_xlfn.IFS(_xlpm.x<0,0,_xlpm.x=0,0,_xlpm.x<=0.5,2,_xlpm.x<=1,3,_xlpm.x<=1.5,4, _xlpm.x<=2,5,_xlpm.x<=3,6,_xlpm.x<=4,7,_xlpm.x<=5,8,_xlpm.x>5,9)), _xlpm.score(_xlpm.a)+_xlpm.score(_xlpm.b))} -> 0 | AA4: {=_xlfn.IFS($W4=0,0,AND($W4>0,$W4<=0.5),2,AND($W4>0.5,$W4<=1),3,AND($W4>1,$W4<=1.5),4,AND($W4>1.5,$W4<=2),5,AND($W4>2,$W4<=3),6,AND($W4>3,$W4<=4),7,$W4>4,8)} -> 0 | AB4: {=_xlfn.IFS($X4=0,0,AND($X4>0,$X4<=0.5),2,AND($X4>0.5,$X4<=1),3,AND($X4>1,$X4<=1.5),4,AND($X4>1.5,$X4<=2),5,AND($X4>2,$X4<=3),6,AND($X4>3,$X4<=4),7,$X4>4,8)} -> 7 | AC4: {=_xlfn.IFS($Y4=0,0,AND($Y4>0,$Y4<=0.5),2,AND($Y4>0.5,$Y4<=1),3,AND($Y4>1,$Y4<=1.5),4,AND($Y4>1.5,$Y4<=2),5,AND($Y4>2,$Y4<=3),6,AND($Y4>3,$Y4<=4),7,$Y4>4,8)} -> 0 | AD4: 3.42 | AE4: 0.54 | AF4: =AD4+AE4 -> 3.96 | AG4: 2568 | AH4: Q3
A5: 2 | B5: กรุงเทพมหานครและปริมณฑล | C5: กรุงเทพมหานคร | D5: หักเสาไฟฟ้า | E5: UG66/MSN/0001 | F5: ถนนจรัญสนิทวงศ์ ช่วงที่ 2 (แยกบางพลัด - ถนนบรมราชชนนี) | G5: 3.7 | H5: BKK1 | I5: 2569 | J5: 45658 | K5: 46081 | L5: Done | M5: ลงใต้ดิน | N5: yes | O5: 920982.58 | P5: 495000 | Q5: Approved | R5: 13.784568460507492, 100.49439125627126 | S5: 13.773351404499168, 100.48190426894638 | T5: 144C | X5: =AF5 -> 4.07 | Z5: {=_xlfn.LET( _xlpm.a,IF(ISNUMBER($U5),$U5,IFERROR(_xlfn.NUMBERVALUE(TRIM($U5)),0)), _xlpm.b,IF(ISNUMBER($V5),$V5,IFERROR(_xlfn.NUMBERVALUE(TRIM($V5)),0)), _xlpm.score,_xlfn.LAMBDA(_xlpm.x,_xlfn.IFS(_xlpm.x<0,0,_xlpm.x=0,0,_xlpm.x<=0.5,2,_xlpm.x<=1,3,_xlpm.x<=1.5,4, _xlpm.x<=2,5,_xlpm.x<=3,6,_xlpm.x<=4,7,_xlpm.x<=5,8,_xlpm.x>5,9)), _xlpm.score(_xlpm.a)+_xlpm.score(_xlpm.b))} -> 0 | AA5: {=_xlfn.IFS($W5=0,0,AND($W5>0,$W5<=0.5),2,AND($W5>0.5,$W5<=1),3,AND($W5>1,$W5<=1.5),4,AND($W5>1.5,$W5<=2),5,AND($W5>2,$W5<=3),6,AND($W5>3,$W5<=4),7,$W5>4,8)} -> 0 | AB5: {=_xlfn.IFS($X5=0,0,AND($X5>0,$X5<=0.5),2,AND($X5>0.5,$X5<=1),3,AND($X5>1,$X5<=1.5),4,AND($X5>1.5,$X5<=2),5,AND($X5>2,$X5<=3),6,AND($X5>3,$X5<=4),7,$X5>4,8)} -> 8 | AC5: {=_xlfn.IFS($Y5=0,0,AND($Y5>0,$Y5<=0.5),2,AND($Y5>0.5,$Y5<=1),3,AND($Y5>1,$Y5<=1.5),4,AND($Y5>1.5,$Y5<=2),5,AND($Y5>2,$Y5<=3),6,AND($Y5>3,$Y5<=4),7,$Y5>4,8)} -> 0 | AD5: 3.515 | AE5: 0.555 | AF5: =AD5+AE5 -> 4.07 | AG5: 2568 | AH5: Q4
A6: 3 | B6: กรุงเทพมหานครและปริมณฑล | C6: กรุงเทพมหานคร | D6: ไม่หักเสาไฟฟ้า | E6: UG66/OTH/0018 | F6: ถนนเยาวราช โซนที่ 5 (2 ฝั่งถนน) (ถนนทรงสวัสดิ์ - ซุ้มประตูเฉลิมพระเกียรติ 6 รอบพระชนมพรรษา) | G6: 0.6 | H6: BKK4 | I6: 2569 | J6: 45716 | K6: 46064 | L6: Done | M6: ลงใต้ดิน | N6: yes | O6: 126596.98 | P6: 36775.272 | Q6: Approved | R6: 13.739407567111556, 100.51147056044779 | S6: 13.737353625608659, 100.51294350981958 | T6: 60C | W6: =AF6 -> 0.66 | Z6: {=_xlfn.LET( _xlpm.a,IF(ISNUMBER($U6),$U6,IFERROR(_xlfn.NUMBERVALUE(TRIM($U6)),0)), _xlpm.b,IF(ISNUMBER($V6),$V6,IFERROR(_xlfn.NUMBERVALUE(TRIM($V6)),0)), _xlpm.score,_xlfn.LAMBDA(_xlpm.x,_xlfn.IFS(_xlpm.x<0,0,_xlpm.x=0,0,_xlpm.x<=0.5,2,_xlpm.x<=1,3,_xlpm.x<=1.5,4, _xlpm.x<=2,5,_xlpm.x<=3,6,_xlpm.x<=4,7,_xlpm.x<=5,8,_xlpm.x>5,9)), _xlpm.score(_xlpm.a)+_xlpm.score(_xlpm.b))} -> 0 | AA6: {=_xlfn.IFS($W6=0,0,AND($W6>0,$W6<=0.5),2,AND($W6>0.5,$W6<=1),3,AND($W6>1,$W6<=1.5),4,AND($W6>1.5,$W6<=2),5,AND($W6>2,$W6<=3),6,AND($W6>3,$W6<=4),7,$W6>4,8)} -> 3 | AB6: {=_xlfn.IFS($X6=0,0,AND($X6>0,$X6<=0.5),2,AND($X6>0.5,$X6<=1),3,AND($X6>1,$X6<=1.5),4,AND($X6>1.5,$X6<=2),5,AND($X6>2,$X6<=3),6,AND($X6>3,$X6<=4),7,$X6>4,8)} -> 0 | AC6: {=_xlfn.IFS($Y6=0,0,AND($Y6>0,$Y6<=0.5),2,AND($Y6>0.5,$Y6<=1),3,AND($Y6>1,$Y6<=1.5),4,AND($Y6>1.5,$Y6<=2),5,AND($Y6>2,$Y6<=3),6,AND($Y6>3,$Y6<=4),7,$Y6>4,8)} -> 0 | AD6: 0.57 | AE6: 0.09 | AF6: =AD6+AE6 -> 0.66 | AG6: 2568 | AH6: Q4
A7: 4 | B7: กรุงเทพมหานครและปริมณฑล | C7: กรุงเทพมหานคร | D7: หักเสาไฟฟ้า | E7: UG68/MSN/0004 | F7: ถนนประชาราษฎร์ สาย 2 (2 ฝั่งถนน) (แยกบางโพ - แม่น้ำเจ้าพระยา) | G7: 0.5 | H7: BKK2 | I7: 2569 | J7: 45808 | K7: 46091 | L7: Done | M7: ลงใต้ดิน | N7: yes | O7: 28750 | P7: 14036.364 | Q7: Approved | R7: 13.80636889371856, 100.52158110006106 | S7: 13.806316740574633, 100.51924673175483 | T7: 60C | W7: =AF7 -> 0.55 | Z7: {=_xlfn.LET( _xlpm.a,IF(ISNUMBER($U7),$U7,IFERROR(_xlfn.NUMBERVALUE(TRIM($U7)),0)), _xlpm.b,IF(ISNUMBER($V7),$V7,IFERROR(_xlfn.NUMBERVALUE(TRIM($V7)),0)), _xlpm.score,_xlfn.LAMBDA(_xlpm.x,_xlfn.IFS(_xlpm.x<0,0,_xlpm.x=0,0,_xlpm.x<=0.5,2,_xlpm.x<=1,3,_xlpm.x<=1.5,4, _xlpm.x<=2,5,_xlpm.x<=3,6,_xlpm.x<=4,7,_xlpm.x<=5,8,_xlpm.x>5,9)), _xlpm.score(_xlpm.a)+_xlpm.score(_xlpm.b))} -> 0 | AA7: {=_xlfn.IFS($W7=0,0,AND($W7>0,$W7<=0.5),2,AND($W7>0.5,$W7<=1),3,AND($W7>1,$W7<=1.5),4,AND($W7>1.5,$W7<=2),5,AND($W7>2,$W7<=3),6,AND($W7>3,$W7<=4),7,$W7>4,8)} -> 3 | AB7: {=_xlfn.IFS($X7=0,0,AND($X7>0,$X7<=0.5),2,AND($X7>0.5,$X7<=1),3,AND($X7>1,$X7<=1.5),4,AND($X7>1.5,$X7<=2),5,AND($X7>2,$X7<=3),6,AND($X7>3,$X7<=4),7,$X7>4,8)} -> 0 | AC7: {=_xlfn.IFS($Y7=0,0,AND($Y7>0,$Y7<=0.5),2,AND($Y7>0.5,$Y7<=1),3,AND($Y7>1,$Y7<=1.5),4,AND($Y7>1.5,$Y7<=2),5,AND($Y7>2,$Y7<=3),6,AND($Y7>3,$Y7<=4),7,$Y7>4,8)} -> 0 | AD7: 0.475 | AE7: 0.075 | AF7: =AD7+AE7 -> 0.55 | AG7: 2569 | AH7: Q2
A8: 5 | B8: กรุงเทพมหานครและปริมณฑล | C8: กรุงเทพมหานคร | D8: หักเสาไฟฟ้า | E8: UG67/MSN/0001 | F8: ถนนประชาราษฎร์ สาย 2 (2 ฝั่งถนน) (แยกประชาชื่น - แยกบางโพ) | G8: 2.8 | H8: BKK2 | I8: 2569 | J8: 45808 | K8: 46077 | L8: Done | M8: ลงใต้ดิน | N8: yes | O8: 161000 | P8: 78603.636 | Q8: Approved | R8: 13.805650769000955, 100.5332038528518 | S8: 13.80636889371856, 100.52158110006106 | T8: 60C | W8: =AF8 -> 3.08 | Z8: {=_xlfn.LET( _xlpm.a,IF(ISNUMBER($U8),$U8,IFERROR(_xlfn.NUMBERVALUE(TRIM($U8)),0)), _xlpm.b,IF(ISNUMBER($V8),$V8,IFERROR(_xlfn.NUMBERVALUE(TRIM($V8)),0)), _xlpm.score,_xlfn.LAMBDA(_xlpm.x,_xlfn.IFS(_xlpm.x<0,0,_xlpm.x=0,0,_xlpm.x<=0.5,2,_xlpm.x<=1,3,_xlpm.x<=1.5,4, _xlpm.x<=2,5,_xlpm.x<=3,6,_xlpm.x<=4,7,_xlpm.x<=5,8,_xlpm.x>5,9)), _xlpm.score(_xlpm.a)+_xlpm.score(_xlpm.b))} -> 0 | AA8: {=_xlfn.IFS($W8=0,0,AND($W8>0,$W8<=0.5),2,AND($W8>0.5,$W8<=1),3,AND($W8>1,$W8<=1.5),4,AND($W8>1.5,$W8<=2),5,AND($W8>2,$W8<=3),6,AND($W8>3,$W8<=4),7,$W8>4,8)} -> 7 | AB8: {=_xlfn.IFS($X8=0,0,AND($X8>0,$X8<=0.5),2,AND($X8>0.5,$X8<=1),3,AND($X8>1,$X8<=1.5),4,AND($X8>1.5,$X8<=2),5,AND($X8>2,$X8<=3),6,AND($X8>3,$X8<=4),7,$X8>4,8)} -> 0 | AC8: {=_xlfn.IFS($Y8=0,0,AND($Y8>0,$Y8<=0.5),2,AND($Y8>0.5,$Y8<=1),3,AND($Y8>1,$Y8<=1.5),4,AND($Y8>1.5,$Y8<=2),5,AND($Y8>2,$Y8<=3),6,AND($Y8>3,$Y8<=4),7,$Y8>4,8)} -> 0 | AD8: 2.66 | AE8: 0.42 | AF8: =AD8+AE8 -> 3.08 | AG8: 2569 | AH8: Q2
A9: 6 | B9: กรุงเทพมหานครและปริมณฑล | C9: กรุงเทพมหานคร | D9: หักเสาไฟฟ้า | E9: UG66/MSN/0003 | F9: ถนนจรัญสนิทวงศ์ ช่วงที่ 2 (2 ฝั่งถนน) (ถนนบรมราชชนนี - ถนนสุทธาวาส) | G9: 3 | H9: BKK1 | I9: 2569 | J9: 45658 | K9: 46111 | L9: Done | M9: ลงใต้ดิน | N9: yes | O9: 637974.77 | P9: 313671.84 | Q9: Approved | R9: 13.773351404499168, 100.48190426894638 | S9: 13.762829108215561, 100.47280943699901 | T9: 60C | W9: =AF9 -> 3.3 | Z9: {=_xlfn.LET( _xlpm.a,IF(ISNUMBER($U9),$U9,IFERROR(_xlfn.NUMBERVALUE(TRIM($U9)),0)), _xlpm.b,IF(ISNUMBER($V9),$V9,IFERROR(_xlfn.NUMBERVALUE(TRIM($V9)),0)), _xlpm.score,_xlfn.LAMBDA(_xlpm.x,_xlfn.IFS(_xlpm.x<0,0,_xlpm.x=0,0,_xlpm.x<=0.5,2,_xlpm.x<=1,3,_xlpm.x<=1.5,4, _xlpm.x<=2,5,_xlpm.x<=3,6,_xlpm.x<=4,7,_xlpm.x<=5,8,_xlpm.x>5,9)), _xlpm.score(_xlpm.a)+_xlpm.score(_xlpm.b))} -> 0 | AA9: {=_xlfn.IFS($W9=0,0,AND($W9>0,$W9<=0.5),2,AND($W9>0.5,$W9<=1),3,AND($W9>1,$W9<=1.5),4,AND($W9>1.5,$W9<=2),5,AND($W9>2,$W9<=3),6,AND($W9>3,$W9<=4),7,$W9>4,8)} -> 7 | AB9: {=_xlfn.IFS($X9=0,0,AND($X9>0,$X9<=0.5),2,AND($X9>0.5,$X9<=1),3,AND($X9>1,$X9<=1.5),4,AND($X9>1.5,$X9<=2),5,AND($X9>2,$X9<=3),6,AND($X9>3,$X9<=4),7,$X9>4,8)} -> 0 | AC9: {=_xlfn.IFS($Y9=0,0,AND($Y9>0,$Y9<=0.5),2,AND($Y9>0.5,$Y9<=1),3,AND($Y9>1,$Y9<=1.5),4,AND($Y9>1.5,$Y9<=2),5,AND($Y9>2,$Y9<=3),6,AND($Y9>3,$Y9<=4),7,$Y9>4,8)} -> 0 | AD9: 2.85 | AE9: 0.45 | AF9: =AD9+AE9 -> 3.3 | AG9: 2568 | AH9: Q1
A10: 7 | B10: กรุงเทพมหานครและปริมณฑล | C10: กรุงเทพมหานคร | D10: ไม่หักเสาไฟฟ้า | E10: UG65/OTH/0001 | F10: ถนนมหาราช (2 ฝั่งถนน) (ถนนหน้าพระลาน - ถนนพระจันทร์) | G10: 1 | H10: BKK4 | I10: 2569 | J10: 45716 | K10: 46112 | L10: n/a | M10: ไม่มีโครงข่าย | N10: no | O10: 0 | P10: 0 | Q10: n/a | R10: 13.752349559081285, 100.48952032574502 | S10: 13.756307989636536, 100.48963246494628 | T10: n/a | Z10: {=_xlfn.LET( _xlpm.a,IF(ISNUMBER($U10),$U10,IFERROR(_xlfn.NUMBERVALUE(TRIM($U10)),0)), _xlpm.b,IF(ISNUMBER($V10),$V10,IFERROR(_xlfn.NUMBERVALUE(TRIM($V10)),0)), _xlpm.score,_xlfn.LAMBDA(_xlpm.x,_xlfn.IFS(_xlpm.x<0,0,_xlpm.x=0,0,_xlpm.x<=0.5,2,_xlpm.x<=1,3,_xlpm.x<=1.5,4, _xlpm.x<=2,5,_xlpm.x<=3,6,_xlpm.x<=4,7,_xlpm.x<=5,8,_xlpm.x>5,9)), _xlpm.score(_xlpm.a)+_xlpm.score(_xlpm.b))} -> 0 | AA10: {=_xlfn.IFS($W10=0,0,AND($W10>0,$W10<=0.5),2,AND($W10>0.5,$W10<=1),3,AND($W10>1,$W10<=1.5),4,AND($W10>1.5,$W10<=2),5,AND($W10>2,$W10<=3),6,AND($W10>3,$W10<=4),7,$W10>4,8)} -> 0 | AB10: {=_xlfn.IFS($X10=0,0,AND($X10>0,$X10<=0.5),2,AND($X10>0.5,$X10<=1),3,AND($X10>1,$X10<=1.5),4,AND($X10>1.5,$X10<=2),5,AND($X10>2,$X10<=3),6,AND($X10>3,$X10<=4),7,$X10>4,8)} -> 0 | AC10: {=_xlfn.IFS($Y10=0,0,AND($Y10>0,$Y10<=0.5),2,AND($Y10>0.5,$Y10<=1),3,AND($Y10>1,$Y10<=1.5),4,AND($Y10>1.5,$Y10<=2),5,AND($Y10>2,$Y10<=3),6,AND($Y10>3,$Y10<=4),7,$Y10>4,8)} -> 0 | AD10: 0 | AE10: 0 | AF10: =AD10+AE10 -> 0 | AG10: n/a | AH10: n/a
A11: 8 | B11: กรุงเทพมหานครและปริมณฑล | C11: กรุงเทพมหานคร | D11: ไม่หักเสาไฟฟ้า | E11: UG66/OTH/0013 | F11: ถนนดินสอ (2 ฝั่งถนน) (ถนนราชดำเนินกลาง - ถนนบำรุงเมือง) | G11: 1 | H11: BKK4 | I11: 2569 | J11: 45716 | K11: 46112 | L11: n/a | M11: ไม่มีโครงข่าย | N11: no | O11: 0 | P11: 0 | Q11: n/a | R11: 13.756336780416937, 100.50172473113246 | S11: 13.751996814090212, 100.50091911156224 | T11: n/a | Z11: {=_xlfn.LET( _xlpm.a,IF(ISNUMBER($U11),$U11,IFERROR(_xlfn.NUMBERVALUE(TRIM($U11)),0)), _xlpm.b,IF(ISNUMBER($V11),$V11,IFERROR(_xlfn.NUMBERVALUE(TRIM($V11)),0)), _xlpm.score,_xlfn.LAMBDA(_xlpm.x,_xlfn.IFS(_xlpm.x<0,0,_xlpm.x=0,0,_xlpm.x<=0.5,2,_xlpm.x<=1,3,_xlpm.x<=1.5,4, _xlpm.x<=2,5,_xlpm.x<=3,6,_xlpm.x<=4,7,_xlpm.x<=5,8,_xlpm.x>5,9)), _xlpm.score(_xlpm.a)+_xlpm.score(_xlpm.b))} -> 0 | AA11: {=_xlfn.IFS($W11=0,0,AND($W11>0,$W11<=0.5),2,AND($W11>0.5,$W11<=1),3,AND($W11>1,$W11<=1.5),4,AND($W11>1.5,$W11<=2),5,AND($W11>2,$W11<=3),6,AND($W11>3,$W11<=4),7,$W11>4,8)} -> 0 | AB11: {=_xlfn.IFS($X11=0,0,AND($X11>0,$X11<=0.5),2,AND($X11>0.5,$X11<=1),3,AND($X11>1,$X11<=1.5),4,AND($X11>1.5,$X11<=2),5,AND($X11>2,$X11<=3),6,AND($X11>3,$X11<=4),7,$X11>4,8)} -> 0 | AC11: {=_xlfn.IFS($Y11=0,0,AND($Y11>0,$Y11<=0.5),2,AND($Y11>0.5,$Y11<=1),3,AND($Y11>1,$Y11<=1.5),4,AND($Y11>1.5,$Y11<=2),5,AND($Y11>2,$Y11<=3),6,AND($Y11>3,$Y11<=4),7,$Y11>4,8)} -> 0 | AD11: 0 | AE11: 0 | AF11: =AD11+AE11 -> 0 | AG11: n/a | AH11: n/a
A12: 9 | B12: กรุงเทพมหานครและปริมณฑล | C12: กรุงเทพมหานคร | D12: ไม่หักเสาไฟฟ้า | E12: UG67/OTH/0007 | F12: ถนนพระจันทร์ (2 ฝั่งถนน) (ถนนมหาราช - ถนนหน้าพระธาตุ) | G12: 0.6 | H12: BKK4 | I12: 2569 | J12: 45716 | K12: 46112 | L12: n/a | M12: ไม่มีโครงข่าย | N12: no | O12: 0 | P12: 0 | Q12: n/a | R12: 13.756315478100502, 100.48962466125836 | S12: 13.755464330915798, 100.49212710949539 | T12: n/a | Z12: {=_xlfn.LET( _xlpm.a,IF(ISNUMBER($U12),$U12,IFERROR(_xlfn.NUMBERVALUE(TRIM($U12)),0)), _xlpm.b,IF(ISNUMBER($V12),$V12,IFERROR(_xlfn.NUMBERVALUE(TRIM($V12)),0)), _xlpm.score,_xlfn.LAMBDA(_xlpm.x,_xlfn.IFS(_xlpm.x<0,0,_xlpm.x=0,0,_xlpm.x<=0.5,2,_xlpm.x<=1,3,_xlpm.x<=1.5,4, _xlpm.x<=2,5,_xlpm.x<=3,6,_xlpm.x<=4,7,_xlpm.x<=5,8,_xlpm.x>5,9)), _xlpm.score(_xlpm.a)+_xlpm.score(_xlpm.b))} -> 0 | AA12: {=_xlfn.IFS($W12=0,0,AND($W12>0,$W12<=0.5),2,AND($W12>0.5,$W12<=1),3,AND($W12>1,$W12<=1.5),4,AND($W12>1.5,$W12<=2),5,AND($W12>2,$W12<=3),6,AND($W12>3,$W12<=4),7,$W12>4,8)} -> 0 | AB12: {=_xlfn.IFS($X12=0,0,AND($X12>0,$X12<=0.5),2,AND($X12>0.5,$X12<=1),3,AND($X12>1,$X12<=1.5),4,AND($X12>1.5,$X12<=2),5,AND($X12>2,$X12<=3),6,AND($X12>3,$X12<=4),7,$X12>4,8)} -> 0 | AC12: {=_xlfn.IFS($Y12=0,0,AND($Y12>0,$Y12<=0.5),2,AND($Y12>0.5,$Y12<=1),3,AND($Y12>1,$Y12<=1.5),4,AND($Y12>1.5,$Y12<=2),5,AND($Y12>2,$Y12<=3),6,AND($Y12>3,$Y12<=4),7,$Y12>4,8)} -> 0 | AD12: 0 | AE12: 0 | AF12: =AD12+AE12 -> 0 | AG12: n/a | AH12: n/a
A13: 10 | B13: กรุงเทพมหานครและปริมณฑล | C13: กรุงเทพมหานคร | D13: ไม่หักเสาไฟฟ้า | E13: UG67/OTH/0008 | F13: ถนนศิริพงษ์ (รอบศาลาว่าการ กทม.) (1 ฝั่งถนน) (ถนนดินสอ - ถนนบำรุงเมือง) | G13: 0.4 | H13: BKK4 | I13: 2569 | J13: 45716 | K13: 46112 | L13: Done | M13: Re-route | N13: no | O13: 32500 | P13: =9650*0.1*12 -> 11580 | Q13: Approved | R13: 13.754652717659106, 100.50137705611867 | S13: 13.751914974521213, 100.50199713785821 | T13: 12C | U13: =AF13 -> 0.44 | Z13: {=_xlfn.LET( _xlpm.a,IF(ISNUMBER($U13),$U13,IFERROR(_xlfn.NUMBERVALUE(TRIM($U13)),0)), _xlpm.b,IF(ISNUMBER($V13),$V13,IFERROR(_xlfn.NUMBERVALUE(TRIM($V13)),0)), _xlpm.score,_xlfn.LAMBDA(_xlpm.x,_xlfn.IFS(_xlpm.x<0,0,_xlpm.x=0,0,_xlpm.x<=0.5,2,_xlpm.x<=1,3,_xlpm.x<=1.5,4, _xlpm.x<=2,5,_xlpm.x<=3,6,_xlpm.x<=4,7,_xlpm.x<=5,8,_xlpm.x>5,9)), _xlpm.score(_xlpm.a)+_xlpm.score(_xlpm.b))} -> 2 | AA13: {=_xlfn.IFS($W13=0,0,AND($W13>0,$W13<=0.5),2,AND($W13>0.5,$W13<=1),3,AND($W13>1,$W13<=1.5),4,AND($W13>1.5,$W13<=2),5,AND($W13>2,$W13<=3),6,AND($W13>3,$W13<=4),7,$W13>4,8)} -> 0 | AB13: {=_xlfn.IFS($X13=0,0,AND($X13>0,$X13<=0.5),2,AND($X13>0.5,$X13<=1),3,AND($X13>1,$X13<=1.5),4,AND($X13>1.5,$X13<=2),5,AND($X13>2,$X13<=3),6,AND($X13>3,$X13<=4),7,$X13>4,8)} -> 0 | AC13: {=_xlfn.IFS($Y13=0,0,AND($Y13>0,$Y13<=0.5),2,AND($Y13>0.5,$Y13<=1),3,AND($Y13>1,$Y13<=1.5),4,AND($Y13>1.5,$Y13<=2),5,AND($Y13>2,$Y13<=3),6,AND($Y13>3,$Y13<=4),7,$Y13>4,8)} -> 0 | AD13: 0.38 | AE13: 0.06 | AF13: =AD13+AE13 -> 0.44 | AG13: 2568 | AH13: Q4
A14: 11 | B14: กรุงเทพมหานครและปริมณฑล | C14: กรุงเทพมหานคร | D14: ไม่หักเสาไฟฟ้า | E14: UG66/OTH/0017 | F14: ถนนเยาวราช โซนที่ 4 ฝั่งใต้ (1 ฝั่งถนน) (ถนนราชวงศ์ - ถนนทรงสวัสดิ์) | G14: 0.6 | H14: BKK4 | I14: 2569 | J14: 45716 | K14: 46064 | L14: Onprocess | M14: ลงใต้ดิน | N14: yes | O14: 126596.98 | P14: 36775.272 | Q14: Approved | R14: 13.742290754376612, 100.50694991095189 | S14: 13.739396707790819, 100.5113779307246 | T14: 60C | W14: =AF14 -> 0.66 | Z14: {=_xlfn.LET( _xlpm.a,IF(ISNUMBER($U14),$U14,IFERROR(_xlfn.NUMBERVALUE(TRIM($U14)),0)), _xlpm.b,IF(ISNUMBER($V14),$V14,IFERROR(_xlfn.NUMBERVALUE(TRIM($V14)),0)), _xlpm.score,_xlfn.LAMBDA(_xlpm.x,_xlfn.IFS(_xlpm.x<0,0,_xlpm.x=0,0,_xlpm.x<=0.5,2,_xlpm.x<=1,3,_xlpm.x<=1.5,4, _xlpm.x<=2,5,_xlpm.x<=3,6,_xlpm.x<=4,7,_xlpm.x<=5,8,_xlpm.x>5,9)), _xlpm.score(_xlpm.a)+_xlpm.score(_xlpm.b))} -> 0 | AA14: {=_xlfn.IFS($W14=0,0,AND($W14>0,$W14<=0.5),2,AND($W14>0.5,$W14<=1),3,AND($W14>1,$W14<=1.5),4,AND($W14>1.5,$W14<=2),5,AND($W14>2,$W14<=3),6,AND($W14>3,$W14<=4),7,$W14>4,8)} -> 3 | AB14: {=_xlfn.IFS($X14=0,0,AND($X14>0,$X14<=0.5),2,AND($X14>0.5,$X14<=1),3,AND($X14>1,$X14<=1.5),4,AND($X14>1.5,$X14<=2),5,AND($X14>2,$X14<=3),6,AND($X14>3,$X14<=4),7,$X14>4,8)} -> 0 | AC14: {=_xlfn.IFS($Y14=0,0,AND($Y14>0,$Y14<=0.5),2,AND($Y14>0.5,$Y14<=1),3,AND($Y14>1,$Y14<=1.5),4,AND($Y14>1.5,$Y14<=2),5,AND($Y14>2,$Y14<=3),6,AND($Y14>3,$Y14<=4),7,$Y14>4,8)} -> 0 | AD14: 0.57 | AE14: 0.09 | AF14: =AD14+AE14 -> 0.66 | AG14: 2568 | AH14: Q4
A15: 12 | B15: กรุงเทพมหานครและปริมณฑล | C15: กรุงเทพมหานคร | D15: หักเสาไฟฟ้า | E15: UG67/MSN/0005 | F15: ถนนลาดพร้าว ช่วงที่ 2 (2 ฝั่งถนน) (ถนนรัชดาภิเษก - ถนนประดิษฐมนูธรรม) | G15: 8.4 | H15: BKK2 | I15: 2569 | J15: 45961 | K15: 46142 | L15: Done | M15: ลงใต้ดิน | N15: yes | O15: 875435.26 | P15: 296626.15 | Q15: Approved | R15: 13.805411917542347, 100.57495144377492 | S15: 13.786437316477445, 100.60875437077863 | T15: 144C | X15: =AF15 -> 9.24 | Z15: {=_xlfn.LET( _xlpm.a,IF(ISNUMBER($U15),$U15,IFERROR(_xlfn.NUMBERVALUE(TRIM($U15)),0)), _xlpm.b,IF(ISNUMBER($V15),$V15,IFERROR(_xlfn.NUMBERVALUE(TRIM($V15)),0)), _xlpm.score,_xlfn.LAMBDA(_xlpm.x,_xlfn.IFS(_xlpm.x<0,0,_xlpm.x=0,0,_xlpm.x<=0.5,2,_xlpm.x<=1,3,_xlpm.x<=1.5,4, _xlpm.x<=2,5,_xlpm.x<=3,6,_xlpm.x<=4,7,_xlpm.x<=5,8,_xlpm.x>5,9)), _xlpm.score(_xlpm.a)+_xlpm.score(_xlpm.b))} -> 0 | AA15: {=_xlfn.IFS($W15=0,0,AND($W15>0,$W15<=0.5),2,AND($W15>0.5,$W15<=1),3,AND($W15>1,$W15<=1.5),4,AND($W15>1.5,$W15<=2),5,AND($W15>2,$W15<=3),6,AND($W15>3,$W15<=4),7,$W15>4,8)} -> 0 | AB15: {=_xlfn.IFS($X15=0,0,AND($X15>0,$X15<=0.5),2,AND($X15>0.5,$X15<=1),3,AND($X15>1,$X15<=1.5),4,AND($X15>1.5,$X15<=2),5,AND($X15>2,$X15<=3),6,AND($X15>3,$X15<=4),7,$X15>4,8)} -> 8 | AC15: {=_xlfn.IFS($Y15=0,0,AND($Y15>0,$Y15<=0.5),2,AND($Y15>0.5,$Y15<=1),3,AND($Y15>1,$Y15<=1.5),4,AND($Y15>1.5,$Y15<=2),5,AND($Y15>2,$Y15<=3),6,AND($Y15>3,$Y15<=4),7,$Y15>4,8)} -> 0 | AD15: 7.98 | AE15: 1.26 | AF15: =AD15+AE15 -> 9.24 | AG15: 2568 | AH15: Q4
A16: 13 | B16: กรุงเทพมหานครและปริมณฑล | C16: กรุงเทพมหานคร | D16: ไม่หักเสาไฟฟ้า | E16: UG66/OTH/0015 | F16: ถนนเยาวราช โซนที่ 2 ฝั่งเหนือ (1 ฝั่งถนน) (ถบนราชวงศ์ - ถนนทรงสวัสดิ์) | G16: 0.6 | H16: BKK4 | I16: 2569 | J16: 45716 | K16: 46064 | L16: Onprocess | M16: ลงใต้ดิน | N16: yes | O16: 126596.98 | P16: 36775.272 | Q16: Approved | R16: 13.742351981932222, 100.50699483795309 | S16: 13.739483313274192, 100.51143472095434 | T16: 60C | W16: =AF16 -> 0.66 | Z16: {=_xlfn.LET( _xlpm.a,IF(ISNUMBER($U16),$U16,IFERROR(_xlfn.NUMBERVALUE(TRIM($U16)),0)), _xlpm.b,IF(ISNUMBER($V16),$V16,IFERROR(_xlfn.NUMBERVALUE(TRIM($V16)),0)), _xlpm.score,_xlfn.LAMBDA(_xlpm.x,_xlfn.IFS(_xlpm.x<0,0,_xlpm.x=0,0,_xlpm.x<=0.5,2,_xlpm.x<=1,3,_xlpm.x<=1.5,4, _xlpm.x<=2,5,_xlpm.x<=3,6,_xlpm.x<=4,7,_xlpm.x<=5,8,_xlpm.x>5,9)), _xlpm.score(_xlpm.a)+_xlpm.score(_xlpm.b))} -> 0 | AA16: {=_xlfn.IFS($W16=0,0,AND($W16>0,$W16<=0.5),2,AND($W16>0.5,$W16<=1),3,AND($W16>1,$W16<=1.5),4,AND($W16>1.5,$W16<=2),5,AND($W16>2,$W16<=3),6,AND($W16>3,$W16<=4),7,$W16>4,8)} -> 3 | AB16: {=_xlfn.IFS($X16=0,0,AND($X16>0,$X16<=0.5),2,AND($X16>0.5,$X16<=1),3,AND($X16>1,$X16<=1.5),4,AND($X16>1.5,$X16<=2),5,AND($X16>2,$X16<=3),6,AND($X16>3,$X16<=4),7,$X16>4,8)} -> 0 | AC16: {=_xlfn.IFS($Y16=0,0,AND($Y16>0,$Y16<=0.5),2,AND($Y16>0.5,$Y16<=1),3,AND($Y16>1,$Y16<=1.5),4,AND($Y16>1.5,$Y16<=2),5,AND($Y16>2,$Y16<=3),6,AND($Y16>3,$Y16<=4),7,$Y16>4,8)} -> 0 | AD16: 0.57 | AE16: 0.09 | AF16: =AD16+AE16 -> 0.66 | AG16: 2568 | AH16: Q4
A17: 14 | B17: กรุงเทพมหานครและปริมณฑล | C17: กรุงเทพมหานคร | D17: หักเสาไฟฟ้า | E17: UG67/OTH/0003 | F17: ถนนวิทยุ ช่วงที่ 2 (2 ฝั่งถนน) (ถนนเพลินจิต - ถนนเพชรบุรี) | G17: 1.6 | H17: BKK4 | I17: 2569 | J17: 45838 | K17: 46173 | L17: Onprocess | M17: ลงใต้ดิน | N17: yes | O17: 166500 | P17: 86850 | Q17: Approved | R17: 13.743321627022501, 100.54756286403692 | S17: 13.749692752378785, 100.54859664430262 | T17: 144C | X17: =AF17 -> 1.76 | Z17: {=_xlfn.LET( _xlpm.a,IF(ISNUMBER($U17),$U17,IFERROR(_xlfn.NUMBERVALUE(TRIM($U17)),0)), _xlpm.b,IF(ISNUMBER($V17),$V17,IFERROR(_xlfn.NUMBERVALUE(TRIM($V17)),0)), _xlpm.score,_xlfn.LAMBDA(_xlpm.x,_xlfn.IFS(_xlpm.x<0,0,_xlpm.x=0,0,_xlpm.x<=0.5,2,_xlpm.x<=1,3,_xlpm.x<=1.5,4, _xlpm.x<=2,5,_xlpm.x<=3,6,_xlpm.x<=4,7,_xlpm.x<=5,8,_xlpm.x>5,9)), _xlpm.score(_xlpm.a)+_xlpm.score(_xlpm.b))} -> 0 | AA17: {=_xlfn.IFS($W17=0,0,AND($W17>0,$W17<=0.5),2,AND($W17>0.5,$W17<=1),3,AND($W17>1,$W17<=1.5),4,AND($W17>1.5,$W17<=2),5,AND($W17>2,$W17<=3),6,AND($W17>3,$W17<=4),7,$W17>4,8)} -> 0 | AB17: {=_xlfn.IFS($X17=0,0,AND($X17>0,$X17<=0.5),2,AND($X17>0.5,$X17<=1),3,AND($X17>1,$X17<=1.5),4,AND($X17>1.5,$X17<=2),5,AND($X17>2,$X17<=3),6,AND($X17>3,$X17<=4),7,$X17>4,8)} -> 5 | AC17: {=_xlfn.IFS($Y17=0,0,AND($Y17>0,$Y17<=0.5),2,AND($Y17>0.5,$Y17<=1),3,AND($Y17>1,$Y17<=1.5),4,AND($Y17>1.5,$Y17<=2),5,AND($Y17>2,$Y17<=3),6,AND($Y17>3,$Y17<=4),7,$Y17>4,8)} -> 0 | AD17: 1.52 | AE17: 0.24 | AF17: =AD17+AE17 -> 1.76 | AG17: 2569 | AH17: Q2
A18: 15 | B18: กรุงเทพมหานครและปริมณฑล | C18: กรุงเทพมหานคร | D18: หักเสาไฟฟ้า | E18: UG65/NTC/0010 | F18: ถนนพระราม 4 ช่วงที่ 2 (2 ฝั่งถนน) (สามย่านมิตรทาวน์ - แยกคลองเตย) | G18: 7.2 | H18: BKK4 | I18: 2569 | J18: 46081 | K18: 46181 | L18: Done | M18: ลงใต้ดิน | N18: no | O18: 5051985.3 | P18: 2417417.1 | Q18: Approved | R18: 13.733353800169416, 100.52750043205424 | S18: 13.720229321195605, 100.55906312982408 | T18: 144C | X18: =AF18 -> 7.92 | Z18: {=_xlfn.LET( _xlpm.a,IF(ISNUMBER($U18),$U18,IFERROR(_xlfn.NUMBERVALUE(TRIM($U18)),0)), _xlpm.b,IF(ISNUMBER($V18),$V18,IFERROR(_xlfn.NUMBERVALUE(TRIM($V18)),0)), _xlpm.score,_xlfn.LAMBDA(_xlpm.x,_xlfn.IFS(_xlpm.x<0,0,_xlpm.x=0,0,_xlpm.x<=0.5,2,_xlpm.x<=1,3,_xlpm.x<=1.5,4, _xlpm.x<=2,5,_xlpm.x<=3,6,_xlpm.x<=4,7,_xlpm.x<=5,8,_xlpm.x>5,9)), _xlpm.score(_xlpm.a)+_xlpm.score(_xlpm.b))} -> 0 | AA18: {=_xlfn.IFS($W18=0,0,AND($W18>0,$W18<=0.5),2,AND($W18>0.5,$W18<=1),3,AND($W18>1,$W18<=1.5),4,AND($W18>1.5,$W18<=2),5,AND($W18>2,$W18<=3),6,AND($W18>3,$W18<=4),7,$W18>4,8)} -> 0 | AB18: {=_xlfn.IFS($X18=0,0,AND($X18>0,$X18<=0.5),2,AND($X18>0.5,$X18<=1),3,AND($X18>1,$X18<=1.5),4,AND($X18>1.5,$X18<=2),5,AND($X18>2,$X18<=3),6,AND($X18>3,$X18<=4),7,$X18>4,8)} -> 8 | AC18: {=_xlfn.IFS($Y18=0,0,AND($Y18>0,$Y18<=0.5),2,AND($Y18>0.5,$Y18<=1),3,AND($Y18>1,$Y18<=1.5),4,AND($Y18>1.5,$Y18<=2),5,AND($Y18>2,$Y18<=3),6,AND($Y18>3,$Y18<=4),7,$Y18>4,8)} -> 0 | AD18: 6.84 | AE18: 1.08 | AF18: =AD18+AE18 -> 7.92 | AG18: 2567 | AH18: Q2
A19: 16 | B19: กรุงเทพมหานครและปริมณฑล | C19: กรุงเทพมหานคร | D19: หักเสาไฟฟ้า | E19: UG66/MSN/0002 | F19: ถนนจรัญสนิทวงศ์ ช่วงที่ 2 (2 ฝั่งอนน) (ถนนสุทธาวาส - ถนนพรานนก) | G19: 2 | H19: BKK1 | I19: 2569 | J19: 45658 | K19: 46203 | L19: Onprocess | M19: ลงใต้ดิน | N19: yes | O19: 425316.52 | P19: 209114.56 | Q19: Approved | R19: 13.762829108215561, 100.47280943699901 | S19: 13.754866084753044, 100.46941322132035 | T19: 60C | W19: =AF19 -> 2.2 | Z19: {=_xlfn.LET( _xlpm.a,IF(ISNUMBER($U19),$U19,IFERROR(_xlfn.NUMBERVALUE(TRIM($U19)),0)), _xlpm.b,IF(ISNUMBER($V19),$V19,IFERROR(_xlfn.NUMBERVALUE(TRIM($V19)),0)), _xlpm.score,_xlfn.LAMBDA(_xlpm.x,_xlfn.IFS(_xlpm.x<0,0,_xlpm.x=0,0,_xlpm.x<=0.5,2,_xlpm.x<=1,3,_xlpm.x<=1.5,4, _xlpm.x<=2,5,_xlpm.x<=3,6,_xlpm.x<=4,7,_xlpm.x<=5,8,_xlpm.x>5,9)), _xlpm.score(_xlpm.a)+_xlpm.score(_xlpm.b))} -> 0 | AA19: {=_xlfn.IFS($W19=0,0,AND($W19>0,$W19<=0.5),2,AND($W19>0.5,$W19<=1),3,AND($W19>1,$W19<=1.5),4,AND($W19>1.5,$W19<=2),5,AND($W19>2,$W19<=3),6,AND($W19>3,$W19<=4),7,$W19>4,8)} -> 6 | AB19: {=_xlfn.IFS($X19=0,0,AND($X19>0,$X19<=0.5),2,AND($X19>0.5,$X19<=1),3,AND($X19>1,$X19<=1.5),4,AND($X19>1.5,$X19<=2),5,AND($X19>2,$X19<=3),6,AND($X19>3,$X19<=4),7,$X19>4,8)} -> 0 | AC19: {=_xlfn.IFS($Y19=0,0,AND($Y19>0,$Y19<=0.5),2,AND($Y19>0.5,$Y19<=1),3,AND($Y19>1,$Y19<=1.5),4,AND($Y19>1.5,$Y19<=2),5,AND($Y19>2,$Y19<=3),6,AND($Y19>3,$Y19<=4),7,$Y19>4,8)} -> 0 | AD19: 1.9 | AE19: 0.3 | AF19: =AD19+AE19 -> 2.2 | AG19: 2568 | AH19: Q1
A20: 17 | B20: กรุงเทพมหานครและปริมณฑล | C20: กรุงเทพมหานคร | D20: ไม่หักเสาไฟฟ้า | E20: UG66/OTH/0016 | F20: ถนนเยาวราช โซนที่ 3 ฝั่งใต้ (1 ฝั่งถนน) (ถนนราชวงศ์ - ถนนจักรวรรดิ) | G20: 0.3 | H20: BKK4 | I20: 2569 | J20: 45716 | K20: 46064 | L20: Done | M20: ลงใต้ดิน | N20: yes | O20: 63298.49 | P20: 18387.636 | Q20: Approved | R20: 13.74235530894268, 100.5069216699699 | S20: 13.744095165929302, 100.50446746701284 | T20: 60C | W20: =AF20 -> 0.33 | Z20: {=_xlfn.LET( _xlpm.a,IF(ISNUMBER($U20),$U20,IFERROR(_xlfn.NUMBERVALUE(TRIM($U20)),0)), _xlpm.b,IF(ISNUMBER($V20),$V20,IFERROR(_xlfn.NUMBERVALUE(TRIM($V20)),0)), _xlpm.score,_xlfn.LAMBDA(_xlpm.x,_xlfn.IFS(_xlpm.x<0,0,_xlpm.x=0,0,_xlpm.x<=0.5,2,_xlpm.x<=1,3,_xlpm.x<=1.5,4, _xlpm.x<=2,5,_xlpm.x<=3,6,_xlpm.x<=4,7,_xlpm.x<=5,8,_xlpm.x>5,9)), _xlpm.score(_xlpm.a)+_xlpm.score(_xlpm.b))} -> 0 | AA20: {=_xlfn.IFS($W20=0,0,AND($W20>0,$W20<=0.5),2,AND($W20>0.5,$W20<=1),3,AND($W20>1,$W20<=1.5),4,AND($W20>1.5,$W20<=2),5,AND($W20>2,$W20<=3),6,AND($W20>3,$W20<=4),7,$W20>4,8)} -> 2 | AB20: {=_xlfn.IFS($X20=0,0,AND($X20>0,$X20<=0.5),2,AND($X20>0.5,$X20<=1),3,AND($X20>1,$X20<=1.5),4,AND($X20>1.5,$X20<=2),5,AND($X20>2,$X20<=3),6,AND($X20>3,$X20<=4),7,$X20>4,8)} -> 0 | AC20: {=_xlfn.IFS($Y20=0,0,AND($Y20>0,$Y20<=0.5),2,AND($Y20>0.5,$Y20<=1),3,AND($Y20>1,$Y20<=1.5),4,AND($Y20>1.5,$Y20<=2),5,AND($Y20>2,$Y20<=3),6,AND($Y20>3,$Y20<=4),7,$Y20>4,8)} -> 0 | AD20: 0.285 | AE20: 0.045 | AF20: =AD20+AE20 -> 0.33 | AG20: 2568 | AH20: Q4
A21: 18 | B21: กรุงเทพมหานครและปริมณฑล | C21: กรุงเทพมหานคร | D21: หักเสาไฟฟ้า | E21: UG68/OTH/0007 | F21: ถนนพระราม 9 ช่วงที่ 1 (2 ฝั่งถนน) (แยกถนนรัชดาภิเษก - คลองชวดใหญ่) | G21: 3.6 | H21: BKK3 | I21: 2569 | J21: 46081 | K21: 46229 | L21: Onprocess | M21: ลงใต้ดิน | N21: yes (Jastel) | O21: 822500 | P21: 405300 | Q21: Approved | R21: 13.75605722785821, 100.5649928410609 | S21: 13.754864464443239, 100.58105671390848 | T21: 144C | X21: =AF21 -> 3.96 | Z21: {=_xlfn.LET( _xlpm.a,IF(ISNUMBER($U21),$U21,IFERROR(_xlfn.NUMBERVALUE(TRIM($U21)),0)), _xlpm.b,IF(ISNUMBER($V21),$V21,IFERROR(_xlfn.NUMBERVALUE(TRIM($V21)),0)), _xlpm.score,_xlfn.LAMBDA(_xlpm.x,_xlfn.IFS(_xlpm.x<0,0,_xlpm.x=0,0,_xlpm.x<=0.5,2,_xlpm.x<=1,3,_xlpm.x<=1.5,4, _xlpm.x<=2,5,_xlpm.x<=3,6,_xlpm.x<=4,7,_xlpm.x<=5,8,_xlpm.x>5,9)), _xlpm.score(_xlpm.a)+_xlpm.score(_xlpm.b))} -> 0 | AA21: {=_xlfn.IFS($W21=0,0,AND($W21>0,$W21<=0.5),2,AND($W21>0.5,$W21<=1),3,AND($W21>1,$W21<=1.5),4,AND($W21>1.5,$W21<=2),5,AND($W21>2,$W21<=3),6,AND($W21>3,$W21<=4),7,$W21>4,8)} -> 0 | AB21: {=_xlfn.IFS($X21=0,0,AND($X21>0,$X21<=0.5),2,AND($X21>0.5,$X21<=1),3,AND($X21>1,$X21<=1.5),4,AND($X21>1.5,$X21<=2),5,AND($X21>2,$X21<=3),6,AND($X21>3,$X21<=4),7,$X21>4,8)} -> 7 | AC21: {=_xlfn.IFS($Y21=0,0,AND($Y21>0,$Y21<=0.5),2,AND($Y21>0.5,$Y21<=1),3,AND($Y21>1,$Y21<=1.5),4,AND($Y21>1.5,$Y21<=2),5,AND($Y21>2,$Y21<=3),6,AND($Y21>3,$Y21<=4),7,$Y21>4,8)} -> 0 | AD21: 3.42 | AE21: 0.54 | AF21: =AD21+AE21 -> 3.96 | AG21: 2569 | AH21: Q3
A22: 19 | B22: กรุงเทพมหานครและปริมณฑล | C22: นนทบุรี | D22: ไม่หักเสาไฟฟ้า | E22: UG65/OTH/0013 | F22: ถนนศรีสมาน (2 ฝั่งถนน) (แยกสวนสมเด็จพระศรีนครินทร์ - ถนนเลียบคลองประปา) | G22: 5.2 | H22: BKK2 | I22: 2569 | J22: 46173 | K22: 46234 | L22: Done | M22: ลงใต้ดิน | N22: yes | O22: 609637.44 | P22: 299150 | Q22: Approved | R22: 13.940560347819595, 100.54209283026739 | S22: 13.934430157181419, 100.56354359702038 | T22: 144C | X22: =AF22 -> 5.72 | Z22: {=_xlfn.LET( _xlpm.a,IF(ISNUMBER($U22),$U22,IFERROR(_xlfn.NUMBERVALUE(TRIM($U22)),0)), _xlpm.b,IF(ISNUMBER($V22),$V22,IFERROR(_xlfn.NUMBERVALUE(TRIM($V22)),0)), _xlpm.score,_xlfn.LAMBDA(_xlpm.x,_xlfn.IFS(_xlpm.x<0,0,_xlpm.x=0,0,_xlpm.x<=0.5,2,_xlpm.x<=1,3,_xlpm.x<=1.5,4, _xlpm.x<=2,5,_xlpm.x<=3,6,_xlpm.x<=4,7,_xlpm.x<=5,8,_xlpm.x>5,9)), _xlpm.score(_xlpm.a)+_xlpm.score(_xlpm.b))} -> 0 | AA22: {=_xlfn.IFS($W22=0,0,AND($W22>0,$W22<=0.5),2,AND($W22>0.5,$W22<=1),3,AND($W22>1,$W22<=1.5),4,AND($W22>1.5,$W22<=2),5,AND($W22>2,$W22<=3),6,AND($W22>3,$W22<=4),7,$W22>4,8)} -> 0 | AB22: {=_xlfn.IFS($X22=0,0,AND($X22>0,$X22<=0.5),2,AND($X22>0.5,$X22<=1),3,AND($X22>1,$X22<=1.5),4,AND($X22>1.5,$X22<=2),5,AND($X22>2,$X22<=3),6,AND($X22>3,$X22<=4),7,$X22>4,8)} -> 8 | AC22: {=_xlfn.IFS($Y22=0,0,AND($Y22>0,$Y22<=0.5),2,AND($Y22>0.5,$Y22<=1),3,AND($Y22>1,$Y22<=1.5),4,AND($Y22>1.5,$Y22<=2),5,AND($Y22>2,$Y22<=3),6,AND($Y22>3,$Y22<=4),7,$Y22>4,8)} -> 0 | AD22: 4.94 | AE22: 0.78 | AF22: =AD22+AE22 -> 5.72 | AG22: 2568 | AH22: Q4
A23: 20 | B23: กรุงเทพมหานครและปริมณฑล | C23: กรุงเทพมหานคร | D23: ไม่หักเสาไฟฟ้า | E23: UG66/OTH/0014 | F23: ถนนเยาวราช โซนที่ 1 ฝั่งเหนือ (1 ฝั่งถนน) (ถนนราชวงศ์ - ถนนจักรวรรดิ) | G23: 0.35 | H23: BKK4 | I23: 2569 | J23: 45716 | K23: 46064 | L23: Done | M23: ลงใต้ดิน | N23: yes | O23: 73848.239 | P23: 21452.242 | Q23: Approved | R23: 13.742402566193277, 100.50696074758135 | S23: 13.744195474119442, 100.50455061549454 | T23: 60C | W23: =AF23 -> 0.385 | Z23: {=_xlfn.LET( _xlpm.a,IF(ISNUMBER($U23),$U23,IFERROR(_xlfn.NUMBERVALUE(TRIM($U23)),0)), _xlpm.b,IF(ISNUMBER($V23),$V23,IFERROR(_xlfn.NUMBERVALUE(TRIM($V23)),0)), _xlpm.score,_xlfn.LAMBDA(_xlpm.x,_xlfn.IFS(_xlpm.x<0,0,_xlpm.x=0,0,_xlpm.x<=0.5,2,_xlpm.x<=1,3,_xlpm.x<=1.5,4, _xlpm.x<=2,5,_xlpm.x<=3,6,_xlpm.x<=4,7,_xlpm.x<=5,8,_xlpm.x>5,9)), _xlpm.score(_xlpm.a)+_xlpm.score(_xlpm.b))} -> 0 | AA23: {=_xlfn.IFS($W23=0,0,AND($W23>0,$W23<=0.5),2,AND($W23>0.5,$W23<=1),3,AND($W23>1,$W23<=1.5),4,AND($W23>1.5,$W23<=2),5,AND($W23>2,$W23<=3),6,AND($W23>3,$W23<=4),7,$W23>4,8)} -> 2 | AB23: {=_xlfn.IFS($X23=0,0,AND($X23>0,$X23<=0.5),2,AND($X23>0.5,$X23<=1),3,AND($X23>1,$X23<=1.5),4,AND($X23>1.5,$X23<=2),5,AND($X23>2,$X23<=3),6,AND($X23>3,$X23<=4),7,$X23>4,8)} -> 0 | AC23: {=_xlfn.IFS($Y23=0,0,AND($Y23>0,$Y23<=0.5),2,AND($Y23>0.5,$Y23<=1),3,AND($Y23>1,$Y23<=1.5),4,AND($Y23>1.5,$Y23<=2),5,AND($Y23>2,$Y23<=3),6,AND($Y23>3,$Y23<=4),7,$Y23>4,8)} -> 0 | AD23: 0.3325 | AE23: 0.0525 | AF23: =AD23+AE23 -> 0.385 | AG23: 2568 | AH23: Q4
A24: 21 | B24: กรุงเทพมหานครและปริมณฑล | C24: กรุงเทพมหานคร | D24: หักเสาไฟฟ้า | E24: UG65/OTH/0002 | F24: ถนนลูกหลวง (1 ฝั่งถนน) (ซอยลูกหลวง 1 - ถนนสามเสน) | G24: 2.3 | H24: BKK4 | I24: 2569 | J24: 45961 | K24: 46235 | L24: Wait Duct (NT) | M24: ลงใต้ดิน+Re-route | N24: yes | O24: 116400 | P24: 57900 | Q24: Request | R24: 13.754718045186001, 100.51747023999916 | S24: 13.769942382856494, 100.50399285429273 | T24: 60C | W24: =AF24 -> 2.53 | Z24: {=_xlfn.LET( _xlpm.a,IF(ISNUMBER($U24),$U24,IFERROR(_xlfn.NUMBERVALUE(TRIM($U24)),0)), _xlpm.b,IF(ISNUMBER($V24),$V24,IFERROR(_xlfn.NUMBERVALUE(TRIM($V24)),0)), _xlpm.score,_xlfn.LAMBDA(_xlpm.x,_xlfn.IFS(_xlpm.x<0,0,_xlpm.x=0,0,_xlpm.x<=0.5,2,_xlpm.x<=1,3,_xlpm.x<=1.5,4, _xlpm.x<=2,5,_xlpm.x<=3,6,_xlpm.x<=4,7,_xlpm.x<=5,8,_xlpm.x>5,9)), _xlpm.score(_xlpm.a)+_xlpm.score(_xlpm.b))} -> 0 | AA24: {=_xlfn.IFS($W24=0,0,AND($W24>0,$W24<=0.5),2,AND($W24>0.5,$W24<=1),3,AND($W24>1,$W24<=1.5),4,AND($W24>1.5,$W24<=2),5,AND($W24>2,$W24<=3),6,AND($W24>3,$W24<=4),7,$W24>4,8)} -> 6 | AB24: {=_xlfn.IFS($X24=0,0,AND($X24>0,$X24<=0.5),2,AND($X24>0.5,$X24<=1),3,AND($X24>1,$X24<=1.5),4,AND($X24>1.5,$X24<=2),5,AND($X24>2,$X24<=3),6,AND($X24>3,$X24<=4),7,$X24>4,8)} -> 0 | AC24: {=_xlfn.IFS($Y24=0,0,AND($Y24>0,$Y24<=0.5),2,AND($Y24>0.5,$Y24<=1),3,AND($Y24>1,$Y24<=1.5),4,AND($Y24>1.5,$Y24<=2),5,AND($Y24>2,$Y24<=3),6,AND($Y24>3,$Y24<=4),7,$Y24>4,8)} -> 0 | AD24: 2.185 | AE24: 0.345 | AF24: =AD24+AE24 -> 2.53 | AG24: 2570 | AH24: Q1
A25: 22 | B25: กรุงเทพมหานครและปริมณฑล | C25: กรุงเทพมหานคร | D25: หักเสาไฟฟ้า | E25: UG66/MSN/0004 | F25: ถนนจรัญสนิทวงศ์ ช่วงที่ 3 (2 ฝั่งถนน) (แยกไฟฉาย - แยกท่าพระ) | G25: 5.8 | H25: BKK1 | I25: 2569 | J25: 45808 | K25: 46264 | L25: Wait Duct (NT) | M25: ลงใต้ดิน | N25: no | O25: 420000 | P25: 277920 | Q25: Request | R25: 13.787687709428189, 100.46870537963544 | S25: 13.729397077147375, 100.47421589346044 | T25: 60C | W25: =AF25 -> 6.38 | Z25: {=_xlfn.LET( _xlpm.a,IF(ISNUMBER($U25),$U25,IFERROR(_xlfn.NUMBERVALUE(TRIM($U25)),0)), _xlpm.b,IF(ISNUMBER($V25),$V25,IFERROR(_xlfn.NUMBERVALUE(TRIM($V25)),0)), _xlpm.score,_xlfn.LAMBDA(_xlpm.x,_xlfn.IFS(_xlpm.x<0,0,_xlpm.x=0,0,_xlpm.x<=0.5,2,_xlpm.x<=1,3,_xlpm.x<=1.5,4, _xlpm.x<=2,5,_xlpm.x<=3,6,_xlpm.x<=4,7,_xlpm.x<=5,8,_xlpm.x>5,9)), _xlpm.score(_xlpm.a)+_xlpm.score(_xlpm.b))} -> 0 | AA25: {=_xlfn.IFS($W25=0,0,AND($W25>0,$W25<=0.5),2,AND($W25>0.5,$W25<=1),3,AND($W25>1,$W25<=1.5),4,AND($W25>1.5,$W25<=2),5,AND($W25>2,$W25<=3),6,AND($W25>3,$W25<=4),7,$W25>4,8)} -> 8 | AB25: {=_xlfn.IFS($X25=0,0,AND($X25>0,$X25<=0.5),2,AND($X25>0.5,$X25<=1),3,AND($X25>1,$X25<=1.5),4,AND($X25>1.5,$X25<=2),5,AND($X25>2,$X25<=3),6,AND($X25>3,$X25<=4),7,$X25>4,8)} -> 0 | AC25: {=_xlfn.IFS($Y25=0,0,AND($Y25>0,$Y25<=0.5),2,AND($Y25>0.5,$Y25<=1),3,AND($Y25>1,$Y25<=1.5),4,AND($Y25>1.5,$Y25<=2),5,AND($Y25>2,$Y25<=3),6,AND($Y25>3,$Y25<=4),7,$Y25>4,8)} -> 0 | AD25: 5.51 | AE25: 0.87 | AF25: =AD25+AE25 -> 6.38 | AG25: 2570 | AH25: Q1
A26: 23 | B26: กรุงเทพมหานครและปริมณฑล | C26: กรุงเทพมหานคร | D26: ไม่หักเสาไฟฟ้า | E26: UG66/OTH/0011 | F26: ถนนเยาวราช โซนที่ 1 (2 ฝั่งถนน) (ถนนจักรวรรดิ - คลองโอ่งอ่าง 1) | G26: 0.3 | H26: BKK4 | I26: 2569 | J26: 45716 | K26: 46064 | L26: Done | M26: ลงใต้ดิน | N26: yes | O26: 63298.49 | P26: 18387.636 | Q26: Approved | R26: 13.744166090823622, 100.50444645343005 | S26: 13.744804819949007, 100.50313484102738 | T26: 60C | W26: =AF26 -> 0.33 | Z26: {=_xlfn.LET( _xlpm.a,IF(ISNUMBER($U26),$U26,IFERROR(_xlfn.NUMBERVALUE(TRIM($U26)),0)), _xlpm.b,IF(ISNUMBER($V26),$V26,IFERROR(_xlfn.NUMBERVALUE(TRIM($V26)),0)), _xlpm.score,_xlfn.LAMBDA(_xlpm.x,_xlfn.IFS(_xlpm.x<0,0,_xlpm.x=0,0,_xlpm.x<=0.5,2,_xlpm.x<=1,3,_xlpm.x<=1.5,4, _xlpm.x<=2,5,_xlpm.x<=3,6,_xlpm.x<=4,7,_xlpm.x<=5,8,_xlpm.x>5,9)), _xlpm.score(_xlpm.a)+_xlpm.score(_xlpm.b))} -> 0 | AA26: {=_xlfn.IFS($W26=0,0,AND($W26>0,$W26<=0.5),2,AND($W26>0.5,$W26<=1),3,AND($W26>1,$W26<=1.5),4,AND($W26>1.5,$W26<=2),5,AND($W26>2,$W26<=3),6,AND($W26>3,$W26<=4),7,$W26>4,8)} -> 2 | AB26: {=_xlfn.IFS($X26=0,0,AND($X26>0,$X26<=0.5),2,AND($X26>0.5,$X26<=1),3,AND($X26>1,$X26<=1.5),4,AND($X26>1.5,$X26<=2),5,AND($X26>2,$X26<=3),6,AND($X26>3,$X26<=4),7,$X26>4,8)} -> 0 | AC26: {=_xlfn.IFS($Y26=0,0,AND($Y26>0,$Y26<=0.5),2,AND($Y26>0.5,$Y26<=1),3,AND($Y26>1,$Y26<=1.5),4,AND($Y26>1.5,$Y26<=2),5,AND($Y26>2,$Y26<=3),6,AND($Y26>3,$Y26<=4),7,$Y26>4,8)} -> 0 | AD26: 0.285 | AE26: 0.045 | AF26: =AD26+AE26 -> 0.33 | AG26: 2568 | AH26: Q4
A27: 24 | B27: กรุงเทพมหานครและปริมณฑล | C27: กรุงเทพมหานคร | D27: หักเสาไฟฟ้า | E27: UG68/OTH/0008 | F27: ถนนประชาราษฎร์สาย 1 (2 ฝั่งถนน) (คลองบางซื่อ - ถนนประชาราษฎร์สาย 2) | G27: 1.5 | H27: BKK2 | I27: 2569 | J27: 46173 | K27: 46279 | L27: Wait Duct (NT) | M27: ลงใต้ดิน+Re-route | N27: yes | O27: 94125 | P27: 86850 | Q27: Approved | R27: 13.799932719041246, 100.52139090233405 | S27: 13.806357300875998, 100.52160430476457 | T27: 60C | W27: =AF27 -> 1.65 | Z27: {=_xlfn.LET( _xlpm.a,IF(ISNUMBER($U27),$U27,IFERROR(_xlfn.NUMBERVALUE(TRIM($U27)),0)), _xlpm.b,IF(ISNUMBER($V27),$V27,IFERROR(_xlfn.NUMBERVALUE(TRIM($V27)),0)), _xlpm.score,_xlfn.LAMBDA(_xlpm.x,_xlfn.IFS(_xlpm.x<0,0,_xlpm.x=0,0,_xlpm.x<=0.5,2,_xlpm.x<=1,3,_xlpm.x<=1.5,4, _xlpm.x<=2,5,_xlpm.x<=3,6,_xlpm.x<=4,7,_xlpm.x<=5,8,_xlpm.x>5,9)), _xlpm.score(_xlpm.a)+_xlpm.score(_xlpm.b))} -> 0 | AA27: {=_xlfn.IFS($W27=0,0,AND($W27>0,$W27<=0.5),2,AND($W27>0.5,$W27<=1),3,AND($W27>1,$W27<=1.5),4,AND($W27>1.5,$W27<=2),5,AND($W27>2,$W27<=3),6,AND($W27>3,$W27<=4),7,$W27>4,8)} -> 5 | AB27: {=_xlfn.IFS($X27=0,0,AND($X27>0,$X27<=0.5),2,AND($X27>0.5,$X27<=1),3,AND($X27>1,$X27<=1.5),4,AND($X27>1.5,$X27<=2),5,AND($X27>2,$X27<=3),6,AND($X27>3,$X27<=4),7,$X27>4,8)} -> 0 | AC27: {=_xlfn.IFS($Y27=0,0,AND($Y27>0,$Y27<=0.5),2,AND($Y27>0.5,$Y27<=1),3,AND($Y27>1,$Y27<=1.5),4,AND($Y27>1.5,$Y27<=2),5,AND($Y27>2,$Y27<=3),6,AND($Y27>3,$Y27<=4),7,$Y27>4,8)} -> 0 | AD27: 1.425 | AE27: 0.225 | AF27: =AD27+AE27 -> 1.65 | AG27: 2569 | AH27: Q2
A28: 25 | B28: กรุงเทพมหานครและปริมณฑล | C28: กรุงเทพมหานคร,สมุทรปราการ | D28: หักเสาไฟฟ้า | E28: UG68/MSN/0005 | F28: ถนนสุขุมวิท ช่วงที่ 2 (2 ฝั่งถนน) (แยกบางนา - ถนนกาญจนาภิเษก) | G28: 10.4 | H28: BKK3 | I28: 2569 | J28: 46203 | K28: 46295 | L28: Onprocess | M28: ลงใต้ดิน | N28: yes | O28: 1313624 | P28: 487132 | Q28: Approved | R28: 13.673313628945984, 100.60678315958604 | S28: 13.630125411559987, 100.58887238374705 | T28: 144C | X28: =AF28 -> 11.44 | Z28: {=_xlfn.LET( _xlpm.a,IF(ISNUMBER($U28),$U28,IFERROR(_xlfn.NUMBERVALUE(TRIM($U28)),0)), _xlpm.b,IF(ISNUMBER($V28),$V28,IFERROR(_xlfn.NUMBERVALUE(TRIM($V28)),0)), _xlpm.score,_xlfn.LAMBDA(_xlpm.x,_xlfn.IFS(_xlpm.x<0,0,_xlpm.x=0,0,_xlpm.x<=0.5,2,_xlpm.x<=1,3,_xlpm.x<=1.5,4, _xlpm.x<=2,5,_xlpm.x<=3,6,_xlpm.x<=4,7,_xlpm.x<=5,8,_xlpm.x>5,9)), _xlpm.score(_xlpm.a)+_xlpm.score(_xlpm.b))} -> 0 | AA28: {=_xlfn.IFS($W28=0,0,AND($W28>0,$W28<=0.5),2,AND($W28>0.5,$W28<=1),3,AND($W28>1,$W28<=1.5),4,AND($W28>1.5,$W28<=2),5,AND($W28>2,$W28<=3),6,AND($W28>3,$W28<=4),7,$W28>4,8)} -> 0 | AB28: {=_xlfn.IFS($X28=0,0,AND($X28>0,$X28<=0.5),2,AND($X28>0.5,$X28<=1),3,AND($X28>1,$X28<=1.5),4,AND($X28>1.5,$X28<=2),5,AND($X28>2,$X28<=3),6,AND($X28>3,$X28<=4),7,$X28>4,8)} -> 8 | AC28: {=_xlfn.IFS($Y28=0,0,AND($Y28>0,$Y28<=0.5),2,AND($Y28>0.5,$Y28<=1),3,AND($Y28>1,$Y28<=1.5),4,AND($Y28>1.5,$Y28<=2),5,AND($Y28>2,$Y28<=3),6,AND($Y28>3,$Y28<=4),7,$Y28>4,8)} -> 0 | AD28: 9.88 | AE28: 1.56 | AF28: =AD28+AE28 -> 11.44 | AG28: 2568 | AH28: Q4
A29: 26 | B29: กรุงเทพมหานครและปริมณฑล | C29: กรุงเทพมหานคร | D29: ไม่หักเสาไฟฟ้า | E29: UG65/OTH/0018 | F29: ถนนวิภาวดีรังสิต ช่วงที่ 4 (2 ฝั่งถนน) (แยกเกษตร - หลักสี่) | G29: 9.4 | H29: BKK2 | I29: 2569 | J29: 46234 | K29: 46305 | L29: Wait Duct (NT) | M29: ลงใต้ดิน | N29: yes | O29: 1212600 | P29: 653112 | Q29: Request | R29: 13.847561540502536, 100.56149019379637 | S29: 13.884322387369098, 100.58169030148558 | T29: 144C | X29: =AF29 -> 10.34 | Z29: {=_xlfn.LET( _xlpm.a,IF(ISNUMBER($U29),$U29,IFERROR(_xlfn.NUMBERVALUE(TRIM($U29)),0)), _xlpm.b,IF(ISNUMBER($V29),$V29,IFERROR(_xlfn.NUMBERVALUE(TRIM($V29)),0)), _xlpm.score,_xlfn.LAMBDA(_xlpm.x,_xlfn.IFS(_xlpm.x<0,0,_xlpm.x=0,0,_xlpm.x<=0.5,2,_xlpm.x<=1,3,_xlpm.x<=1.5,4, _xlpm.x<=2,5,_xlpm.x<=3,6,_xlpm.x<=4,7,_xlpm.x<=5,8,_xlpm.x>5,9)), _xlpm.score(_xlpm.a)+_xlpm.score(_xlpm.b))} -> 0 | AA29: {=_xlfn.IFS($W29=0,0,AND($W29>0,$W29<=0.5),2,AND($W29>0.5,$W29<=1),3,AND($W29>1,$W29<=1.5),4,AND($W29>1.5,$W29<=2),5,AND($W29>2,$W29<=3),6,AND($W29>3,$W29<=4),7,$W29>4,8)} -> 0 | AB29: {=_xlfn.IFS($X29=0,0,AND($X29>0,$X29<=0.5),2,AND($X29>0.5,$X29<=1),3,AND($X29>1,$X29<=1.5),4,AND($X29>1.5,$X29<=2),5,AND($X29>2,$X29<=3),6,AND($X29>3,$X29<=4),7,$X29>4,8)} -> 8 | AC29: {=_xlfn.IFS($Y29=0,0,AND($Y29>0,$Y29<=0.5),2,AND($Y29>0.5,$Y29<=1),3,AND($Y29>1,$Y29<=1.5),4,AND($Y29>1.5,$Y29<=2),5,AND($Y29>2,$Y29<=3),6,AND($Y29>3,$Y29<=4),7,$Y29>4,8)} -> 0 | AD29: 8.93 | AE29: 1.41 | AF29: =AD29+AE29 -> 10.34 | AG29: 2570 | AH29: Q2
A30: 27 | B30: กรุงเทพมหานครและปริมณฑล | C30: กรุงเทพมหานคร | D30: หักเสาไฟฟ้า | E30: UG69/MSN/0001 | F30: ถนนตก (2 ฝั่งถนน) (ถนนพระราม 3 - กฟน.ยานนาวา) | G30: 1.1 | H30: BKK4 | I30: 2569 | J30: 46568 | L30: Wait Duct (NT) | M30: Re-route | N30: no | O30: 33600 | P30: =9650*0.2*12 -> 23160 | Q30: Request | R30: 13.697176484650662, 100.49704267467271 | S30: 13.69308524940448, 100.4924692323161 | T30: 12C | U30: =AF30 -> 1.21 | Z30: {=_xlfn.LET( _xlpm.a,IF(ISNUMBER($U30),$U30,IFERROR(_xlfn.NUMBERVALUE(TRIM($U30)),0)), _xlpm.b,IF(ISNUMBER($V30),$V30,IFERROR(_xlfn.NUMBERVALUE(TRIM($V30)),0)), _xlpm.score,_xlfn.LAMBDA(_xlpm.x,_xlfn.IFS(_xlpm.x<0,0,_xlpm.x=0,0,_xlpm.x<=0.5,2,_xlpm.x<=1,3,_xlpm.x<=1.5,4, _xlpm.x<=2,5,_xlpm.x<=3,6,_xlpm.x<=4,7,_xlpm.x<=5,8,_xlpm.x>5,9)), _xlpm.score(_xlpm.a)+_xlpm.score(_xlpm.b))} -> 4 | AA30: {=_xlfn.IFS($W30=0,0,AND($W30>0,$W30<=0.5),2,AND($W30>0.5,$W30<=1),3,AND($W30>1,$W30<=1.5),4,AND($W30>1.5,$W30<=2),5,AND($W30>2,$W30<=3),6,AND($W30>3,$W30<=4),7,$W30>4,8)} -> 0 | AB30: {=_xlfn.IFS($X30=0,0,AND($X30>0,$X30<=0.5),2,AND($X30>0.5,$X30<=1),3,AND($X30>1,$X30<=1.5),4,AND($X30>1.5,$X30<=2),5,AND($X30>2,$X30<=3),6,AND($X30>3,$X30<=4),7,$X30>4,8)} -> 0 | AC30: {=_xlfn.IFS($Y30=0,0,AND($Y30>0,$Y30<=0.5),2,AND($Y30>0.5,$Y30<=1),3,AND($Y30>1,$Y30<=1.5),4,AND($Y30>1.5,$Y30<=2),5,AND($Y30>2,$Y30<=3),6,AND($Y30>3,$Y30<=4),7,$Y30>4,8)} -> 0 | AD30: 1.045 | AE30: 0.165 | AF30: =AD30+AE30 -> 1.21 | AG30: 2571 | AH30: Q1
